Workbook
Name GANADOR_REAL: LAMBDA(cell, cell2, cell3, cell4, IFS(ISBLANK(cell2),"",cell2>cell4,cell,cell4>cell2,cell3,CELL2=CELL4,"EMPATE"))
Name GOLES_FAVOR: LAMBDA(cell, cell2, cell3, CELL+CELL2+CELL3)
Name GANADOR_MARCADOR_POLLA: LAMBDA(cell1, cell2, cell3, cell4, IF(cell1>cell3,cell2,IF(cell3>cell1,cell4,"EMPATE")))
Name JUGADOS: LAMBDA(cell, cell2, cell3, IF(ISBLANK(cell),0,1)+IF(ISBLANK(cell2),0,1)+IF(ISBLANK(cell3),0,1))
Name GOLES_CONTRA: LAMBDA(cell, cell2, cell3, CELL+CELL2+CELL3)

Sheet Ganadores Parciales
A1: Nombre | B1: Puntaje Parcial Fase de Grupos | C1: Puntaje Parcial Octavos de Final | D1: Puntaje Cuartos de Final | E1: Puntajes Semi Final | F1: Puntajes Final | G1: Puntaje Acumulado
A2: ='Puntajes Fases de Grupos'!A3 -> Mauricio Perez (Mauro chef) | B2: ='Puntajes Fases de Grupos'!CT3 -> 92 | C2: =VLOOKUP(A2,'Puntajes Octavos de Final'!$A$3:$R$31,18,0) -> 19 | D2: =VLOOKUP(A2,'Puntajes Cuartos de Final'!$A$3:$J$31,10,0) -> 6 | E2: =VLOOKUP(A2,'Puntajes Semifinal'!$A$3:$F$31,6,0) -> 7 | F2: =VLOOKUP(A2,'Puntajes Final'!A3:F31,6,0) | G2: =SUM(B2,C2,D2,E2) -> 124
A3: ='Puntajes Fases de Grupos'!A25 -> El cuculeito del balon | B3: ='Puntajes Fases de Grupos'!CT25 -> 92 | C3: =VLOOKUP(A3,'Puntajes Octavos de Final'!$A$3:$R$31,18,0) -> 15 | D3: =VLOOKUP(A3,'Puntajes Cuartos de Final'!$A$3:$J$31,10,0) -> 6 | E3: =VLOOKUP(A3,'Puntajes Semifinal'!$A$3:$F$31,6,0) -> 3 | F3: =VLOOKUP(A3,'Puntajes Final'!A4:F32,6,0) -> #N/A | G3: =SUM(B3,C3,D3,E3) -> 116
A4: ='Puntajes Fases de Grupos'!A24 -> TV y Novelas | B4: ='Puntajes Fases de Grupos'!CT24 -> 82 | C4: =VLOOKUP(A4,'Puntajes Octavos de Final'!$A$3:$R$31,18,0) -> 24 | D4: =VLOOKUP(A4,'Puntajes Cuartos de Final'!$A$3:$J$31,10,0) -> 6 | E4: =VLOOKUP(A4,'Puntajes Semifinal'!$A$3:$F$31,6,0) -> 5 | F4: =VLOOKUP(A4,'Puntajes Final'!A5:F33,6,0) -> #N/A | G4: =SUM(B4,C4,D4,E4) -> 117
A5: ='Puntajes Fases de Grupos'!A23 -> Qatarsis 2.0 | B5: ='Puntajes Fases de Grupos'!CT23 -> 84 | C5: =VLOOKUP(A5,'Puntajes Octavos de Final'!$A$3:$R$31,18,0) -> 23 | D5: =VLOOKUP(A5,'Puntajes Cuartos de Final'!$A$3:$J$31,10,0) -> 4 | E5: =VLOOKUP(A5,'Puntajes Semifinal'!$A$3:$F$31,6,0) -> 0 | F5: =VLOOKUP(A5,'Puntajes Final'!A6:F34,6,0) -> #N/A | G5: =SUM(B5,C5,D5,E5) -> 111
A6: ='Puntajes Fases de Grupos'!A27 -> La Perripolla | B6: ='Puntajes Fases de Grupos'!CT27 -> 81 | C6: =VLOOKUP(A6,'Puntajes Octavos de Final'!$A$3:$R$31,18,0) -> 19 | D6: =VLOOKUP(A6,'Puntajes Cuartos de Final'!$A$3:$J$31,10,0) -> 8 | E6: =VLOOKUP(A6,'Puntajes Semifinal'!$A$3:$F$31,6,0) -> 3 | F6: =VLOOKUP(A6,'Puntajes Final'!A7:F35,6,0) -> #N/A | G6: =SUM(B6,C6,D6,E6) -> 111
A7: ='Puntajes Fases de Grupos'!A29 -> Lolita | B7: ='Puntajes Fases de Grupos'!CT29 -> 76 | C7: =VLOOKUP(A7,'Puntajes Octavos de Final'!$A$3:$R$31,18,0) -> 20 | D7: =VLOOKUP(A7,'Puntajes Cuartos de Final'!$A$3:$J$31,10,0) -> 3 | E7: =VLOOKUP(A7,'Puntajes Semifinal'!$A$3:$F$31,6,0) -> 5 | F7: =VLOOKUP(A7,'Puntajes Final'!A8:F36,6,0) -> #N/A | G7: =SUM(B7,C7,D7,E7) -> 104
A8: ='Puntajes Fases de Grupos'!A11 -> Luchismo | B8: ='Puntajes Fases de Grupos'!CT11 -> 74 | C8: =VLOOKUP(A8,'Puntajes Octavos de Final'!$A$3:$R$31,18,0) -> 15 | D8: =VLOOKUP(A8,'Puntajes Cuartos de Final'!$A$3:$J$31,10,0) -> 8 | E8: =VLOOKUP(A8,'Puntajes Semifinal'!$A$3:$F$31,6,0) -> 0 | F8: =VLOOKUP(A8,'Puntajes Final'!A9:F37,6,0) -> #N/A | G8: =SUM(B8,C8,D8,E8) -> 97
A9: ='Puntajes Fases de Grupos'!A28 -> Ana Maria Corpas | B9: ='Puntajes Fases de Grupos'!CT28 -> 79 | C9: =VLOOKUP(A9,'Puntajes Octavos de Final'!$A$3:$R$31,18,0) -> 15 | D9: =VLOOKUP(A9,'Puntajes Cuartos de Final'!$A$3:$J$31,10,0) -> 6 | E9: =VLOOKUP(A9,'Puntajes Semifinal'!$A$3:$F$31,6,0) -> 3 | F9: =VLOOKUP(A9,'Puntajes Final'!A10:F38,6,0) -> #N/A | G9: =SUM(B9,C9,D9,E9) -> 103
A10: ='Puntajes Fases de Grupos'!A20 -> Andres & Cia | B10: ='Puntajes Fases de Grupos'!CT20 -> 77 | C10: =VLOOKUP(A10,'Puntajes Octavos de Final'!$A$3:$R$31,18,0) -> 15 | D10: =VLOOKUP(A10,'Puntajes Cuartos de Final'!$A$3:$J$31,10,0) -> 3 | E10: =VLOOKUP(A10,'Puntajes Semifinal'!$A$3:$F$31,6,0) -> 2 | F10: =VLOOKUP(A10,'Puntajes Final'!A11:F39,6,0) -> #N/A | G10: =SUM(B10,C10,D10,E10) -> 97
A11: ='Puntajes Fases de Grupos'!A31 -> Leonardo Valencia Valencia | B11: ='Puntajes Fases de Grupos'!CT31 -> 73 | C11: =VLOOKUP(A11,'Puntajes Octavos de Final'!$A$3:$R$31,18,0) -> 18 | D11: =VLOOKUP(A11,'Puntajes Cuartos de Final'!$A$3:$J$31,10,0) -> 3 | E11: =VLOOKUP(A11,'Puntajes Semifinal'!$A$3:$F$31,6,0) -> 3 | F11: =VLOOKUP(A11,'Puntajes Final'!A12:F40,6,0) -> #N/A | G11: =SUM(B11,C11,D11,E11) -> 97
A12: ='Puntajes Fases de Grupos'!A14 -> Guanabano Indigente | B12: ='Puntajes Fases de Grupos'!CT14 -> 72 | C12: =VLOOKUP(A12,'Puntajes Octavos de Final'!$A$3:$R$31,18,0) -> 16 | D12: =VLOOKUP(A12,'Puntajes Cuartos de Final'!$A$3:$J$31,10,0) -> 8 | E12: =VLOOKUP(A12,'Puntajes Semifinal'!$A$3:$F$31,6,0) -> 5 | F12: =VLOOKUP(A12,'Puntajes Final'!A13:F41,6,0) -> #N/A | G12: =SUM(B12,C12,D12,E12) -> 101
A13: ='Puntajes Fases de Grupos'!A30 -> Club Atletico Vodka Juniors | B13: ='Puntajes Fases de Grupos'!CT30 -> 73 | C13: =VLOOKUP(A13,'Puntajes Octavos de Final'!$A$3:$R$31,18,0) -> 14 | D13: =VLOOKUP(A13,'Puntajes Cuartos de Final'!$A$3:$J$31,10,0) -> 6 | E13: =VLOOKUP(A13,'Puntajes Semifinal'!$A$3:$F$31,6,0) -> 5 | F13: =VLOOKUP(A13,'Puntajes Final'!A14:F42,6,0) -> #N/A | G13: =SUM(B13,C13,D13,E13) -> 98
A14: ='Puntajes Fases de Grupos'!A7 -> Emerson Alexis Gomez | B14: ='Puntajes Fases de Grupos'!CT7 -> 69 | C14: =VLOOKUP(A14,'Puntajes Octavos de Final'!$A$3:$R$31,18,0) -> 17 | D14: =VLOOKUP(A14,'Puntajes Cuartos de Final'!$A$3:$J$31,10,0) -> 7 | E14: =VLOOKUP(A14,'Puntajes Semifinal'!$A$3:$F$31,6,0) -> 0 | F14: =VLOOKUP(A14,'Puntajes Final'!A15:F43,6,0) -> #N/A | G14: =SUM(B14,C14,D14,E14) -> 93
A15: ='Puntajes Fases de Grupos'!A5 -> Pascual | B15: ='Puntajes Fases de Grupos'!CT5 -> 72 | C15: =VLOOKUP(A15,'Puntajes Octavos de Final'!$A$3:$R$31,18,0) -> 17 | D15: =VLOOKUP(A15,'Puntajes Cuartos de Final'!$A$3:$J$31,10,0) -> 3 | E15: =VLOOKUP(A15,'Puntajes Semifinal'!$A$3:$F$31,6,0) -> 5 | F15: =VLOOKUP(A15,'Puntajes Final'!A16:F44,6,0) -> #N/A | G15: =SUM(B15,C15,D15,E15) -> 97
A16: ='Puntajes Fases de Grupos'!A6 -> Juan Esteban Montoya Hincapie | B16: ='Puntajes Fases de Grupos'!CT6 -> 70 | C16: =VLOOKUP(A16,'Puntajes Octavos de Final'!$A$3:$R$31,18,0) -> 13 | D16: =VLOOKUP(A16,'Puntajes Cuartos de Final'!$A$3:$J$31,10,0) -> 9 | E16: =VLOOKUP(A16,'Puntajes Semifinal'!$A$3:$F$31,6,0) -> 3 | F16: =VLOOKUP(A16,'Puntajes Final'!A17:F45,6,0) -> #N/A | G16: =SUM(B16,C16,D16,E16) -> 95
A17: ='Puntajes Fases de Grupos'!A9 -> Casa VIII | B17: ='Puntajes Fases de Grupos'!CT9 -> 72 | C17: =VLOOKUP(A17,'Puntajes Octavos de Final'!$A$3:$R$31,18,0) -> 16 | D17: =VLOOKUP(A17,'Puntajes Cuartos de Final'!$A$3:$J$31,10,0) -> 2 | E17: =VLOOKUP(A17,'Puntajes Semifinal'!$A$3:$F$31,6,0) -> 7 | F17: =VLOOKUP(A17,'Puntajes Final'!A18:F46,6,0) -> #N/A | G17: =SUM(B17,C17,D17,E17) -> 97
A18: ='Puntajes Fases de Grupos'!A21 -> Las tejedoras | B18: ='Puntajes Fases de Grupos'!CT21 -> 72 | C18: =VLOOKUP(A18,'Puntajes Octavos de Final'!$A$3:$R$31,18,0) -> 14 | D18: =VLOOKUP(A18,'Puntajes Cuartos de Final'!$A$3:$J$31,10,0) -> 4 | E18: =VLOOKUP(A18,'Puntajes Semifinal'!$A$3:$F$31,6,0) -> 6 | F18: =VLOOKUP(A18,'Puntajes Final'!A19:F47,6,0) -> #N/A | G18: =SUM(B18,C18,D18,E18) -> 96
A19: ='Puntajes Fases de Grupos'!A26 -> Cristina Valentina Echeverri- Las fieras | B19: ='Puntajes Fases de Grupos'!CT26 -> 70 | C19: =VLOOKUP(A19,'Puntajes Octavos de Final'!$A$3:$R$31,18,0) -> 16 | D19: =VLOOKUP(A19,'Puntajes Cuartos de Final'!$A$3:$J$31,10,0) -> 2 | E19: =VLOOKUP(A19,'Puntajes Semifinal'!$A$3:$F$31,6,0) -> 3 | F19: =VLOOKUP(A19,'Puntajes Final'!A20:F48,6,0) -> #N/A | G19: =SUM(B19,C19,D19,E19) -> 91
A20: ='Puntajes Fases de Grupos'!A18 -> John Jaramillo-Diogenes Restrepo | B20: ='Puntajes Fases de Grupos'!CT18 -> 68 | C20: =VLOOKUP(A20,'Puntajes Octavos de Final'!$A$3:$R$31,18,0) -> 10 | D20: =VLOOKUP(A20,'Puntajes Cuartos de Final'!$A$3:$J$31,10,0) -> 8 | E20: =VLOOKUP(A20,'Puntajes Semifinal'!$A$3:$F$31,6,0) -> 3 | F20: =VLOOKUP(A20,'Puntajes Final'!A21:F49,6,0) -> #N/A | G20: =SUM(B20,C20,D20,E20) -> 89
A21: ='Puntajes Fases de Grupos'!A10 -> Luis Fermin Naranjo Artehourtua | B21: ='Puntajes Fases de Grupos'!CT10 -> 67 | C21: =VLOOKUP(A21,'Puntajes Octavos de Final'!$A$3:$R$31,18,0) -> 16 | D21: =VLOOKUP(A21,'Puntajes Cuartos de Final'!$A$3:$J$31,10,0) -> 2 | E21: =VLOOKUP(A21,'Puntajes Semifinal'!$A$3:$F$31,6,0) -> 6 | F21: =VLOOKUP(A21,'Puntajes Final'!A22:F50,6,0) -> #N/A | G21: =SUM(B21,C21,D21,E21) -> 91
A22: ='Puntajes Fases de Grupos'!A16 -> Marta Restrepo | B22: ='Puntajes Fases de Grupos'!CT16 -> 75 | C22: =VLOOKUP(A22,'Puntajes Octavos de Final'!$A$3:$R$31,18,0) -> 7 | D22: =VLOOKUP(A22,'Puntajes Cuartos de Final'!$A$3:$J$31,10,0) -> 2 | E22: =VLOOKUP(A22,'Puntajes Semifinal'!$A$3:$F$31,6,0) -> 3 | F22: =VLOOKUP(A22,'Puntajes Final'!A23:F51,6,0) -> #N/A | G22: =SUM(B22,C22,D22,E22) -> 87
A23: ='Puntajes Fases de Grupos'!A13 -> Alejandro Botero | B23: ='Puntajes Fases de Grupos'!CT13 -> 63 | C23: =VLOOKUP(A23,'Puntajes Octavos de Final'!$A$3:$R$31,18,0) -> 16 | D23: =VLOOKUP(A23,'Puntajes Cuartos de Final'!$A$3:$J$31,10,0) -> 4 | E23: =VLOOKUP(A23,'Puntajes Semifinal'!$A$3:$F$31,6,0) -> 3 | F23: =VLOOKUP(A23,'Puntajes Final'!A24:F52,6,0) -> #N/A | G23: =SUM(B23,C23,D23,E23) -> 86
A24: ='Puntajes Fases de Grupos'!A8 -> Pregunte por lo que no vea | B24: ='Puntajes Fases de Grupos'!CT8 -> 66 | C24: =VLOOKUP(A24,'Puntajes Octavos de Final'!$A$3:$R$31,18,0) -> 11 | D24: =VLOOKUP(A24,'Puntajes Cuartos de Final'!$A$3:$J$31,10,0) -> 6 | E24: =VLOOKUP(A24,'Puntajes Semifinal'!$A$3:$F$31,6,0) -> 4 | F24: =VLOOKUP(A24,'Puntajes Final'!A25:F53,6,0) -> #N/A | G24: =SUM(B24,C24,D24,E24) -> 87
A25: ='Puntajes Fases de Grupos'!A17 -> Alex Garcia | B25: ='Puntajes Fases de Grupos'!CT17 -> 64 | C25: =VLOOKUP(A25,'Puntajes Octavos de Final'!$A$3:$R$31,18,0) -> 16 | D25: =VLOOKUP(A25,'Puntajes Cuartos de Final'!$A$3:$J$31,10,0) -> 2 | E25: =VLOOKUP(A25,'Puntajes Semifinal'!$A$3:$F$31,6,0) -> 2 | F25: =VLOOKUP(A25,'Puntajes Final'!A26:F54,6,0) -> #N/A | G25: =SUM(B25,C25,D25,E25) -> 84
A26: ='Puntajes Fases de Grupos'!A15 -> Safiro y Acero | B26: ='Puntajes Fases de Grupos'!CT15 -> 63 | C26: =VLOOKUP(A26,'Puntajes Octavos de Final'!$A$3:$R$31,18,0) -> 15 | D26: =VLOOKUP(A26,'Puntajes Cuartos de Final'!$A$3:$J$31,10,0) -> 4 | E26: =VLOOKUP(A26,'Puntajes Semifinal'!$A$3:$F$31,6,0) -> 5 | F26: =VLOOKUP(A26,'Puntajes Final'!A27:F55,6,0) -> #N/A | G26: =SUM(B26,C26,D26,E26) -> 87
A27: ='Puntajes Fases de Grupos'!A19 -> Los Betancruz | B27: ='Puntajes Fases de Grupos'!CT19 -> 62 | C27: =VLOOKUP(A27,'Puntajes Octavos de Final'!$A$3:$R$31,18,0) -> 12 | D27: =VLOOKUP(A27,'Puntajes Cuartos de Final'!$A$3:$J$31,10,0) -> 6 | E27: =VLOOKUP(A27,'Puntajes Semifinal'!$A$3:$F$31,6,0) -> 3 | F27: =VLOOKUP(A27,'Puntajes Final'!A28:F56,6,0) -> #N/A | G27: =SUM(B27,C27,D27,E27) -> 83
A28: ='Puntajes Fases de Grupos'!A4 -> La qatarsis mundial | B28: ='Puntajes Fases de Grupos'!CT4 -> 55 | C28: =VLOOKUP(A28,'Puntajes Octavos de Final'!$A$3:$R$31,18,0) -> 14 | D28: =VLOOKUP(A28,'Puntajes Cuartos de Final'!$A$3:$J$31,10,0) -> 11 | E28: =VLOOKUP(A28,'Puntajes Semifinal'!$A$3:$F$31,6,0) -> 2 | F28: =VLOOKUP(A28,'Puntajes Final'!A29:F57,6,0) -> #N/A | G28: =SUM(B28,C28,D28,E28) -> 82
A29: ='Puntajes Fases de Grupos'!A22 -> Qatarsis 1.0 | B29: ='Puntajes Fases de Grupos'!CT22 -> 59 | C29: =VLOOKUP(A29,'Puntajes Octavos de Final'!$A$3:$R$31,18,0) -> 18 | D29: =VLOOKUP(A29,'Puntajes Cuartos de Final'!$A$3:$J$31,10,0) -> 4 | E29: =VLOOKUP(A29,'Puntajes Semifinal'!$A$3:$F$31,6,0) -> 1 | F29: =VLOOKUP(A29,'Puntajes Final'!A30:F58,6,0) -> #N/A | G29: =SUM(B29,C29,D29,E29) -> 82
A30: ='Puntajes Fases de Grupos'!A12 -> Lore Mira | B30: ='Puntajes Fases de Grupos'!CT12 -> 48 | C30: =VLOOKUP(A30,'Puntajes Octavos de Final'!$A$3:$R$31,18,0) -> 14 | D30: =VLOOKUP(A30,'Puntajes Cuartos de Final'!$A$3:$J$31,10,0) -> 5 | E30: =VLOOKUP(A30,'Puntajes Semifinal'!$A$3:$F$31,6,0) -> 0 | F30: =VLOOKUP(A30,'Puntajes Final'!A31:F59,6,0) -> #N/A | G30: =SUM(B30,C30,D30,E30) -> 67

Sheet Polla Final
D1: Argentina Vs Francia | F1: Croacia Vs Marruecos
A2: Marca temporal | B2: Dirección de correo electrónico | C2: Nombre | D2: Argentina | E2: Francia | F2: Croacia | G2: Marruecos
A3: 44911.507 | B3: boterovillegas2001@gmail.com | C3: Alejandro Botero | D3: 3 | E3: 1 | F3: 1 | G3: 3
A4: 44911.518 | B4: juandalr97@gmail.com | C4: Marta Restrepo | D4: 8 | E4: 0 | F4: 4 | G4: 4
A5: 44911.765 | B5: andrea.giraldogarcia@gmail.com | C5: Las Tejedoras | D5: 2 | E5: 2 | F5: 2 | G5: 0
A6: 44911.81 | B6: miralorena@gmail.com | C6: TV y Novelas | D6: 1 | E6: 0 | F6: 1 | G6: 2
A7: 44911.816 | B7: leonardo.valenciav@gmail.com | C7: Leonardo Valencia | D7: 2 | E7: 2 | F7: 3 | G7: 2
A8: 44911.827 | B8: mcuidador@gmail.com | C8: Mauricio Perez (Mauro chef) | D8: 1 | E8: 2 | F8: 1 | G8: 0
A9: 44911.87 | B9: vickastro8@gmail.com | C9: CasaVIII | D9: 2 | E9: 1 | F9: 0 | G9: 1
A10: 44911.887 | B10: miralorena@gmail.com | C10: Lore Mira | D10: 2 | E10: 1 | F10: 1 | G10: 1
A11: 44911.905 | B11: luisasanta@gmail.com | C11: La Qatarsis mundial | D11: 2 | E11: 2 | F11: 1 | G11: 2
A12: 44911.951 | B12: adri.patri74@gmail.com | C12: Zafiro y Acero | D12: 3 | E12: 1 | F12: 0 | G12: 2
A13: 44911.969 | B13: nanacorpas@gmail.com | C13: Ana Maria Corpas | D13: 1 | E13: 2 | F13: 2 | G13: 1
A14: 44911.975 | B14: juanmanuelmontoya@hotmail.com | C14: Cristina Valentina Echeverry-Las fieras | D14: 1 | E14: 1 | F14: 1 | G14: 2
... A17: 44912.483 | B17: danielabedoyamartinez@gmail.com | C17: Lolita | D17: 2 | E17: 1 | F17: 2 | G17: 1
C18: Andres y Cia. | D18: 3 | E18: 3 | F18: 2 | G18: 2
C19: Pregunte por lo que no vea | D19: 2 | E19: 0 | F19: 2 | G19: 1
C20: Pascual | D20: 1 | E20: 2 | F20: 1 | G20: 2
C21: El cuculeito del balon | D21: 2 | E21: 1 | F21: 2 | G21: 0
C22: Qatarsis 1.0 | D22: 1 | E22: 3 | F22: 2 | G22: 1
C23: Qatarsis 2.0 | D23: 2 | E23: 2 | F23: 0 | G23: 1
C24: John Jaramillo-Diogenes Restrepo | D24: 3 | E24: 1 | F24: 1 | G24: 2
C25: Luchismo | D25: 2 | E25: 1 | F25: 0 | G25: 1
C26: Guanabano Indigente | D26: 2 | E26: 1 | F26: 1 | G26: 1
C27: La Perripolla | D27: 3 | E27: 2 | F27: 2 | G27: 0

Sheet Pollas Semifinal
D1: Argentina Vs Croacia | F1: Francia Vs Marruecos
A2: Marca temporal | B2: Dirección de correo electrónico | C2: Nombre | D2: Argentina | E2: Croacia | F2: Francia | G2: Marruecos
A3: 44907.866 | B3: mcuidador@gmail.com | C3: Mauricio Perez (Mauro chef) | D3: 2 | E3: 1 | F3: 2 | G3: 0
A4: 44907.866 | B4: leonardo.valenciav@gmail.com | C4: Leonardo Valencia Valencia | D4: 1 | E4: 1 | F4: 2 | G4: 1
A5: 44907.867 | B5: marespezazul@msn.com | C5: Marta Restrepo | D5: 2 | E5: 0 | F5: 1 | G5: 1
A6: 44907.867 | B6: diegojoseduquegomez@gmail.com | C6: Emerson Alexis Gomez | D6: 1 | E6: 2 | F6: 0 | G6: 1
A7: 44907.868 | B7: luisasanta@gmail.com | C7: La qatarsis mundial | D7: 0 | E7: 0 | F7: 2 | G7: 3
A8: 44907.869 | B8: miralorena@gmail.com | C8: Lore Mira | D8: 1 | E8: 2 | F8: 0 | G8: 2
A9: 44907.87 | B9: miralorena@gmail.com | C9: TV y Novelas | D9: 1 | E9: 1 | F9: 2 | G9: 0
A10: 44907.871 | B10: luifernaranjo@gmail.com | C10: Luis Fermin Naranjo Artehourtua | D10: 3 | E10: 1 | F10: 2 | G10: 1
A11: 44907.874 | B11: andrea.giraldogarcia@gmail.com | C11: Las Tejedoras | D11: 1 | E11: 0 | F11: 1 | G11: 0
A12: 44907.884 | B12: danielabedoyamartinez@gmail.com | C12: Lolita | D12: 2 | E12: 1 | F12: 1 | G12: 0
A13: 44907.897 | B13: anambetancurj2022@gmail.com | C13: Los Betancruz | D13: 1 | E13: 1 | F13: 1 | G13: 0
A14: 44907.903 | B14: hadadelanoche00@gmail.com | C14: Qatarsis 1.0 | D14: 1 | E14: 2 | F14: 0 | G14: 0
... A31: 44908.698 | B31: gilipollaguanabano@gmail.com | C31: Guanabano Indigene | D31: 2 | E31: 1 | F31: 3 | G31: 0
C33: Safiro y Acero | D33: 2 | E33: 1 | F33: 2 | G33: 1
C34: John Jaramillo-Diogenes Restrepo | D34: 2 | E34: 0 | F34: 0 | G34: 1
C35: Luchismo | D35: 1 | E35: 1 | F35: 0 | G35: 1
C36: Cristina Valencia Echeverrri-Las fieras | D36: 1 | E36: 2 | F36: 2 | G36: 1
C37: La Perripolla | D37: 1 | E37: 1 | F37: 2 | G37: 1
C38: Ana María Corpas | D38: 1 | E38: 2 | F38: 3 | G38: 0
C39: Guanabano Indigente | D39: 2 | E39: 1 | F39: 3 | G39: 0

Sheet Pollas Cuartos de Final
D1: Croacia Vs Brasil | F1: Argentina Vs Paises Bajos | H1: Marruecos Vs Portugal | J1: Inglaterra Vs Francia
A2: Marca temporal | B2: Dirección de correo electrónico | C2: Nombre | D2: Croacia | E2: Brasil | F2: Argentina | G2: Paises Bajos | H2: Marruecos | I2: Portugal | J2: Inglaterra | K2: Francia
A3: 44903.538 | B3: diegojoseduquegomez@gmail.com | C3: Emerson Alexis Gomez | D3: 1 | E3: 4 | F3: 2 | G3: 3 | H3: 1 | I3: 2 | J3: 1 | K3: 2
A4: 44903.542 | B4: davidjaramillog@hotmail.com | C4: Club Atletico Vodka Juniors | D4: 1 | E4: 2 | F4: 2 | G4: 1 | H4: 0 | I4: 3 | J4: 1 | K4: 2
A5: 44903.546 | B5: danielabedoyamartinez@gmail.com | C5: Lolita | D5: 1 | E5: 3 | F5: 2 | G5: 1 | H5: 1 | I5: 2 | J5: 2 | K5: 2
A6: 44903.55 | B6: juanmontoya.derecho@gmail.com | C6: Juan Esteban Montoya Hincapie | D6: 1 | E6: 1 | F6: 2 | G6: 0 | H6: 2 | I6: 1 | J6: 1 | K6: 2
A7: 44903.552 | B7: boterovillegas2001@gmail.com | C7: Alejandro Botero | D7: 0 | E7: 1 | F7: 1 | G7: 1 | H7: 1 | I7: 2 | J7: 1 | K7: 1
A8: 44903.561 | B8: luisasanta@gmail.com | C8: La qatarsis mundial | D8: 1 | E8: 5 | F8: 2 | G8: 2 | H8: 1 | I8: 3 | J8: 1 | K8: 2
A9: 44903.563 | B9: miralorena@gmail.com | C9: Lore Mira | D9: 2 | E9: 0 | F9: 1 | G9: 3 | H9: 2 | I9: 0 | J9: 2 | K9: 2
A10: 44903.703 | B10: cristimesa26@gmail.com | C10: Pregunte por lo que no vea | D10: 1 | E10: 2 | F10: 2 | G10: 1 | H10: 3 | I10: 2 | J10: 0 | K10: 2
A11: 44903.746 | B11: vickastro8@gmail.com | C11: Casa VIII | D11: 1 | E11: 3 | F11: 2 | G11: 1 | H11: 0 | I11: 2 | J11: 2 | K11: 2
A12: 44903.775 | B12: axlgarcia1984@gmail.com | C12: Alex Garcia | D12: 1 | E12: 3 | F12: 1 | G12: 0 | H12: 1 | I12: 2 | J12: 2 | K12: 2
A13: 44903.805 | B13: juandalr97@gmail.com | C13: Marta Restrepo | D13: 1 | E13: 3 | F13: 5 | G13: 0 | H13: 1 | I13: 1 | J13: 2 | K13: 2
A14: 44903.81 | B14: mcuidador@gmail.com | C14: Mauricio Perez (Mauro chef) | D14: 1 | E14: 3 | F14: 1 | G14: 2 | H14: 0 | I14: 2 | J14: 1 | K14: 2
... A22: 44904.386 | B22: luifernaranjo@gmail.com | C22: Luis Fermin Naranjo Artehourtua | D22: 1 | E22: 3 | F22: 2 | G22: 1 | H22: 2 | I22: 2 | J22: 3 | K22: 2
C23: John Jaramillo-Diogenes Restrepo | D23: 0 | E23: 3 | F23: 2 | G23: 0 | H23: 1 | I23: 1 | J23: 1 | K23: 2
C24: Cristina Valentina Echeverri- Las fieras | D24: 2 | E24: 3 | F24: 1 | G24: 2 | H24: 0 | I24: 1 | J24: 2 | K24: 2
C25: Leonardo Valencia Valencia | D25: 1 | E25: 4 | F25: 3 | G25: 1 | H25: 2 | I25: 2 | J25: 1 | K25: 3
C26: Qatarsis 1.0 | D26: 0 | E26: 3 | F26: 1 | G26: 2 | H26: 1 | I26: 3 | J26: 3 | K26: 2
C27: Qatarsis 2.0 | D27: 0 | E27: 3 | F27: 2 | G27: 1 | H27: 1 | I27: 2 | J27: 2 | K27: 2
C28: La Perripolla | D28: 0 | E28: 2 | F28: 1 | G28: 1 | H28: 1 | I28: 2 | J28: 1 | K28: 2
C29: Guanabano Indigente | D29: 1 | E29: 3 | F29: 2 | G29: 2 | H29: 1 | I29: 1 | J29: 2 | K29: 3
C30: Safiro y Acero | D30: 0 | E30: 2 | F30: 1 | G30: 0 | H30: 1 | I30: 2 | J30: 2 | K30: 3
C31: Luchismo | D31: 0 | E31: 3 | F31: 2 | G31: 2 | H31: 1 | I31: 2 | J31: 1 | K31: 1

Sheet Pollas Octavos de Final
D1: 1A Vs 2B | F1: 1B Vs 2A | H1: 1C Vs 2D | J1: 1D Vs 2C | L1: 1E Vs 2F | N1: 1F Vs 2E | P1: 1G Vs 2H | R1: 1H Vs 2G
A2: Marca temporal | B2: Dirección de correo electrónico | C2: Nombre | D2: Paises Bajos | E2: Estados Unidos | F2: Inglaterra | G2: Senegal | H2: Argentina | I2: Australia | J2: Francia | K2: Polonia | L2: Japón | M2: Croacia | N2: Marruecos | O2: España | P2: Brasil | Q2: Corea del Sur | R2: Portugal | S2: Suiza
A3: 44897.76 | B3: boterovillegas2001@gmail.com | C3: Alejandro Botero | D3: 1 | E3: 0 | F3: 2 | G3: 1 | H3: 1 | I3: 0 | J3: 2 | K3: 1 | L3: 3 | M3: 1 | N3: 2 | O3: 2 | P3: 3 | Q3: 1 | R3: 1 | S3: 0
A4: 44897.768 | B4: nanacorpas@gmail.com | C4: Ana Maria Corpas | D4: 2 | E4: 1 | F4: 3 | G4: 1 | H4: 3 | I4: 0 | J4: 2 | K4: 1 | L4: 2 | M4: 0 | N4: 2 | O4: 2 | P4: 2 | Q4: 1 | R4: 2 | S4: 2
A5: 44897.77 | B5: juandalr97@gmail.com | C5: Marta Restrepo | D5: 1 | E5: 2 | F5: 2 | G5: 0 | H5: 3 | I5: 0 | J5: 1 | K5: 2 | L5: 2 | M5: 0 | N5: 1 | O5: 0 | P5: 1 | Q5: 2 | R5: 1 | S5: 1
A6: 44897.784 | B6: axlgarcia1984@gmail.com | C6: Alex Garcia | D6: 1 | E6: 1 | F6: 2 | G6: 1 | H6: 2 | I6: 0 | J6: 3 | K6: 1 | L6: 3 | M6: 1 | N6: 3 | O6: 2 | P6: 3 | Q6: 0 | R6: 2 | S6: 0
A7: 44897.798 | B7: miralorena@gmail.com | C7: Lore Mira | D7: 2 | E7: 1 | F7: 2 | G7: 2 | H7: 2 | I7: 0 | J7: 1 | K7: 1 | L7: 2 | M7: 1 | N7: 0 | O7: 2 | P7: 3 | Q7: 0 | R7: 2 | S7: 1
A8: 44897.801 | B8: andrea.giraldogarcia@gmail.com | C8: Las tejedoras | D8: 1 | E8: 2 | F8: 0 | G8: 0 | H8: 2 | I8: 0 | J8: 2 | K8: 0 | L8: 1 | M8: 1 | N8: 1 | O8: 1 | P8: 2 | Q8: 0 | R8: 1 | S8: 2
A9: 44897.804 | B9: diegojoseduquegomez@gmail.com | C9: Emerson Alexis Gomez | D9: 2 | E9: 1 | F9: 2 | G9: 1 | H9: 2 | I9: 0 | J9: 2 | K9: 1 | L9: 2 | M9: 0 | N9: 1 | O9: 0 | P9: 3 | Q9: 0 | R9: 2 | S9: 1
A10: 44897.832 | B10: davidjaramillog@hotmail.com | C10: Club Atletico Vodka Juniors | D10: 0 | E10: 1 | F10: 1 | G10: 0 | H10: 2 | I10: 0 | J10: 2 | K10: 0 | L10: 1 | M10: 0 | N10: 1 | O10: 2 | P10: 2 | Q10: 0 | R10: 2 | S10: 0
A11: 44897.833 | B11: juanmontoya.derecho@gmail.com | C11: Juan Esteban Montoya Hincapie | D11: 2 | E11: 1 | F11: 2 | G11: 1 | H11: 2 | I11: 0 | J11: 2 | K11: 0 | L11: 2 | M11: 1 | N11: 1 | O11: 2 | P11: 2 | Q11: 0 | R11: 1 | S11: 2
A12: 44897.834 | B12: danielabedoyamartinez@gmail.com | C12: Lolita | D12: 2 | E12: 1 | F12: 1 | G12: 0 | H12: 2 | I12: 0 | J12: 2 | K12: 0 | L12: 1 | M12: 1 | N12: 1 | O12: 3 | P12: 2 | Q12: 0 | R12: 2 | S12: 0
A13: 44897.852 | B13: mcuidador@gmail.com | C13: Mauricio Perez (Mauro chef) | D13: 2 | E13: 0 | F13: 1 | G13: 0 | H13: 2 | I13: 1 | J13: 3 | K13: 0 | L13: 2 | M13: 1 | N13: 0 | O13: 2 | P13: 2 | Q13: 0 | R13: 2 | S13: 0
A14: 44897.879 | B14: leonardo.valenciav@gmail.com | C14: Leonardo Valencia Valencia | D14: 2 | E14: 0 | F14: 3 | G14: 1 | H14: 2 | I14: 0 | J14: 2 | K14: 1 | L14: 1 | M14: 0 | N14: 1 | O14: 1 | P14: 3 | Q14: 1 | R14: 2 | S14: 0
... A19: 44898.402 | B19: cristimesa26@gmail.com | C19: Pregunte por lo que no vea | D19: 2 | E19: 1 | F19: 1 | G19: 1 | H19: 2 | I19: 0 | J19: 1 | K19: 0 | L19: 1 | M19: 2 | N19: 2 | O19: 3 | P19: 2 | Q19: 0 | R19: 2 | S19: 2
B20: lauracamersi803@gmail.com | C20: La Perripolla | D20: 1 | E20: 0 | F20: 3 | G20: 1 | H20: 2 | I20: 1 | J20: 2 | K20: 0 | L20: 2 | M20: 1 | N20: 1 | O20: 1 | P20: 3 | Q20: 0 | R20: 2 | S20: 1
C21: John Jaramillo-Diogenes Restrepo | D21: 1 | E21: 2 | F21: 1 | G21: 2 | H21: 2 | I21: 0 | J21: 2 | K21: 1 | L21: 1 | M21: 0 | N21: 2 | O21: 1 | P21: 1 | Q21: 0 | R21: 1 | S21: 1
B22: correavanegas25@gmail.com | C22: Andres & Cia | D22: 1 | E22: 1 | F22: 2 | G22: 1 | H22: 3 | I22: 0 | J22: 3 | K22: 1 | L22: 2 | M22: 3 | N22: 2 | O22: 2 | P22: 3 | Q22: 1 | R22: 1 | S22: 1
B23: manuelmontoya@yahoo.com | C23: Cristina Valentina Echeverri- Las fieras | D23: 2 | E23: 1 | F23: 3 | G23: 1 | H23: 4 | I23: 0 | J23: 3 | K23: 0 | L23: 0 | M23: 1 | N23: 1 | O23: 2 | P23: 2 | Q23: 1 | R23: 1 | S23: 1
B24: piritadehierro@gmail.com | C24: Safiro y Acero | D24: 2 | E24: 1 | F24: 3 | G24: 0 | H24: 3 | I24: 1 | J24: 2 | K24: 2 | L24: 2 | M24: 1 | N24: 2 | O24: 1 | P24: 2 | Q24: 1 | R24: 1 | S24: 3
B25: Qatarsis 1.0 | C25: Qatarsis 1.0 | D25: 2 | E25: 1 | F25: 3 | G25: 0 | H25: 2 | I25: 0 | J25: 3 | K25: 0 | L25: 1 | M25: 2 | N25: 2 | O25: 2 | P25: 2 | Q25: 0 | R25: 1 | S25: 2
B26: Qatarsis 2.0 | C26: Qatarsis 2.0 | D26: 2 | E26: 0 | F26: 1 | G26: 0 | H26: 2 | I26: 1 | J26: 3 | K26: 1 | L26: 1 | M26: 1 | N26: 2 | O26: 1 | P26: 3 | Q26: 0 | R26: 1 | S26: 1
B27: sandra.barrientos@udea.edu.co | C27: Guanabano Indigente | D27: 1 | E27: 1 | F27: 2 | G27: 1 | H27: 2 | I27: 1 | J27: 3 | K27: 0 | L27: 2 | M27: 1 | N27: 1 | O27: 1 | P27: 3 | Q27: 0 | R27: 1 | S27: 1
B28: anambetancurj2022@gmail.com | C28: Los Betancruz | D28: 1 | E28: 3 | F28: 1 | G28: 0 | H28: 2 | I28: 0 | J28: 3 | K28: 0 | L28: 2 | M28: 0 | N28: 1 | O28: 1 | P28: 2 | Q28: 0 | R28: 0 | S28: 0
C29: Luchismo | D29: 2 | E29: 1 | F29: 2 | G29: 2 | H29: 3 | I29: 1 | J29: 3 | K29: 0 | L29: 2 | M29: 0 | N29: 0 | O29: 1 | P29: 4 | Q29: 0 | R29: 3 | S29: 2
C30: Pascual | D30: 1 | E30: 2 | F30: 3 | G30: 0 | H30: 3 | I30: 0 | J30: 3 | K30: 0 | L30: 1 | M30: 2 | N30: 0 | O30: 2 | P30: 3 | Q30: 0 | R30: 2 | S30: 1
C31: El cuculeito del balon | D31: 2 | E31: 0 | F31: 2 | G31: 1 | H31: 2 | I31: 0 | J31: 2 | K31: 0 | L31: 0 | M31: 1 | N31: 0 | O31: 2 | P31: 2 | Q31: 0 | R31: 1 | S31: 0

Sheet Pollas Fase de Grupos
D1: Qatar vs Ecuador | F1: Senegal vs Paises Bajos | H1: Qatar vs Senegal | J1: Paises Bajos vs Ecuador | L1: Paises Bajos vs Qatar | N1: Ecuador vs Senegal | P1: Inglaterra vs Iran | R1: Estados Unidos vs Gales | T1: Inglaterra vs Estados Unidos | V1: Gales vs Iran | X1: Gales vs Inglaterra | Z1: Iran vs Estados Unidos | AB1: Argentina vs Arabia Saudita | AD1: Mexico vs Polonia | AF1: Argentina vs Mexico | AH1: Polonia vs Arabia Saudita | AJ1: Polonia vs Argentina | AL1: Arabia Saudita vs Mexico | AN1: Francia vs Australia | AP1: Dinamarca vs Tunez | AR1: Francia vs Dinamarca | AT1: Tunez vs Australia | AV1: Tunez vs Francia | AX1: Australia vs Dinamarca | AZ1: España vs Costa Rica | BB1: Alemania vs Japon | BD1: España vs Alemania | BF1: Japón vs Costa Rica | BH1: Japón vs España | BJ1: Costa Rica vs Alemania | BL1: Belgica vs Canada | BN1: Marruecos vs Croacia | BP1: Belgica vs Marruecos | BR1: Croacia vs Canada | BT1: Croacia vs Belgica | BV1: Canada vs Marruecos | BX1: Brasil vs Serbia | BZ1: Suiza vs Camerun | CB1: Brasil vs Suiza | CD1: Camerun vs Serbia | CF1: Camerun vs Brasil | CH1: Serbia vs Suiza | CJ1: Portugal vs Ghana | CL1: Uruguay vs Corea del Sur | CN1: Portugal vs Uruguay | CP1: Corea del Sur vs Ghana | CR1: Corea del Sur vs Portugal | CT1: Ghana vs Uruguay
A2: Marca temporal | B2: Dirección de correo electrónico | C2: Seleccione el Grupo | D2: Qatar | E2: Ecuador | F2: Senegal | G2: Paises Bajos | H2: Qatar | I2: Senegal | J2: Paises Bajos | K2: Ecuador | L2: Paises Bajos | M2: Qatar | N2: Ecuador | O2: Senegal | P2: Inglaterra | Q2: Iran | R2: Estados Unidos | S2: Gales | T2: Inglaterra | U2: Estados Unidos | V2: Gales | W2: Iran | X2: Gales | Y2: Inglaterra | Z2: Iran | AA2: Estados Unidos | AB2: Argentina | AC2: Arabia Saudita | AD2: Mexico | AE2: Polonia | AF2: Argentina | AG2: Mexico | AH2: Polonia | AI2: Arabia Saudita | AJ2: Polonia | AK2: Argentina | AL2: Arabia Saudita | AM2: Mexico | AN2: Francia | AO2: Australia | AP2: Dinamarca | AQ2: Tunez | AR2: Francia | AS2: Dinamarca | AT2: Tunez | AU2: Australia | AV2: Tunez | AW2: Francia | AX2: Australia | AY2: Dinamarca | AZ2: España | BA2: Costa Rica | BB2: Alemania | BC2: Japon | BD2: España | BE2: Alemania | BF2: Japon | BG2: Costa Rica | BH2: Japon | BI2: España | BJ2: Costa Rica | BK2: Alemania | BL2: Belgica | BM2: Canada | BN2: Marruecos | BO2: Croacia | BP2: Belgica | BQ2: Marruecos | BR2: Croacia | BS2: Canada | BT2: Croacia | BU2: Belgica | BV2: Canada | BW2: Marruecos | BX2: Brasil | BY2: Serbia | BZ2: Suiza | CA2: Camerun | CB2: Brasil | CC2: Suiza | CD2: Camerun | CE2: Serbia | CF2: Camerun | CG2: Brasil | CH2: Serbia | CI2: Suiza | CJ2: Portugal | CK2: Ghana | CL2: Uruguay | CM2: Corea del Sur | CN2: Portugal | CO2: Uruguay | CP2: Corea del Sur | CQ2: Ghana | CR2: Corea del Sur | CS2: Portugal | CT2: Ghana | CU2: Uruguay | CV2: Nombre | CW2: Goleador del mundial | CX2: Valla menos vencida | CY2: Equipo más goleador
A3: 44883.928 | B3: mcuidador@gmail.com | C3: Grupo H | D3: 1 | E3: 0 | F3: 0 | G3: 2 | H3: 0 | I3: 1 | J3: 2 | K3: 0 | L3: 2 | M3: 1 | N3: 1 | O3: 1 | P3: 2 | Q3: 0 | R3: 1 | S3: 1 | T3: 2 | U3: 0 | V3: 2 | W3: 1 | X3: 0 | Y3: 2 | Z3: 0 | AA3: 1 | AB3: 2 | AC3: 0 | AD3: 1 | AE3: 1 | AF3: 2 | AG3: 0 | AH3: 1 | AI3: 0 | AJ3: 1 | AK3: 2 | AL3: 0 | AM3: 2 | AN3: 3 | AO3: 0 | AP3: 2 | AQ3: 0 | AR3: 2 | AS3: 1 | AT3: 0 | AU3: 1 | AV3: 0 | AW3: 3 | AX3: 1 | AY3: 2 | AZ3: 2 | BA3: 0 | BB3: 2 | BC3: 0 | BD3: 1 | BE3: 2 | BF3: 1 | BG3: 1 | BH3: 0 | BI3: 2 | BJ3: 0 | BK3: 3 | BL3: 1 | BM3: 0 | BN3: 1 | BO3: 2 | BP3: 2 | BQ3: 0 | BR3: 2 | BS3: 1 | BT3: 0 | BU3: 1 | BV3: 0 | BW3: 2 | BX3: 2 | BY3: 0 | BZ3: 1 | CA3: 1 | CB3: 2 | CC3: 1 | CD3: 2 | CE3: 0 | CF3: 1 | CG3: 2 | CH3: 0 | CI3: 1 | CJ3: 2 | CK3: 0 | CL3: 1 | CM3: 0 | CN3: 1 | CO3: 0 | CP3: 0 | CQ3: 1 | CR3: 0 | CS3: 2 | CT3: 1 | CU3: 0 | CV3: Mauricio Perez (Mauro chef) | CW3: Kylian Mbappe | CX3: Francia | CY3: Francia
A4: 44884.511 | B4: luisasanta@gmail.com | C4: Grupo H | D4: 1 | E4: 2 | F4: 2 | G4: 3 | H4: 1 | I4: 1 | J4: 2 | K4: 0 | L4: 1 | M4: 1 | N4: 2 | O4: 2 | P4: 2 | Q4: 1 | R4: 0 | S4: 0 | T4: 3 | U4: 0 | V4: 2 | W4: 2 | X4: 3 | Y4: 3 | Z4: 1 | AA4: 0 | AB4: 3 | AC4: 1 | AD4: 2 | AE4: 0 | AF4: 1 | AG4: 1 | AH4: 2 | AI4: 1 | AJ4: 0 | AK4: 0 | AL4: 0 | AM4: 0 | AN4: 4 | AO4: 0 | AP4: 1 | AQ4: 0 | AR4: 1 | AS4: 1 | AT4: 0 | AU4: 0 | AV4: 0 | AW4: 2 | AX4: 1 | AY4: 2 | AZ4: 3 | BA4: 2 | BB4: 5 | BC4: 1 | BD4: 0 | BE4: 1 | BF4: 1 | BG4: 2 | BH4: 0 | BI4: 3 | BJ4: 1 | BK4: 1 | BL4: 3 | BM4: 0 | BN4: 0 | BO4: 1 | BP4: 2 | BQ4: 1 | BR4: 2 | BS4: 0 | BT4: 1 | BU4: 1 | BV4: 0 | BW4: 0 | BX4: 3 | BY4: 1 | BZ4: 0 | CA4: 0 | CB4: 2 | CC4: 1 | CD4: 1 | CE4: 1 | CF4: 2 | CG4: 2 | CH4: 0 | CI4: 1 | CJ4: 2 | CK4: 0 | CL4: 0 | CM4: 0 | CN4: 2 | CO4: 2 | CP4: 0 | CQ4: 1 | CR4: 0 | CS4: 4 | CT4: 1 | CU4: 3 | CV4: La qatarsis mundial | CW4: Kylian Mbappe | CX4: Argentina | CY4: Brasil
A5: 44884.517 | B5: rabodeajip@hotmail.com | C5: Grupo H | D5: 1 | E5: 1 | F5: 0 | G5: 2 | H5: 1 | I5: 2 | J5: 2 | K5: 0 | L5: 3 | M5: 1 | N5: 1 | O5: 1 | P5: 3 | Q5: 0 | R5: 2 | S5: 0 | T5: 1 | U5: 0 | V5: 0 | W5: 0 | X5: 1 | Y5: 2 | Z5: 0 | AA5: 1 | AB5: 3 | AC5: 0 | AD5: 1 | AE5: 1 | AF5: 2 | AG5: 0 | AH5: 2 | AI5: 1 | AJ5: 0 | AK5: 1 | AL5: 0 | AM5: 2 | AN5: 2 | AO5: 0 | AP5: 1 | AQ5: 0 | AR5: 2 | AS5: 2 | AT5: 2 | AU5: 1 | AV5: 1 | AW5: 3 | AX5: 0 | AY5: 1 | AZ5: 2 | BA5: 0 | BB5: 2 | BC5: 0 | BD5: 2 | BE5: 1 | BF5: 1 | BG5: 1 | BH5: 1 | BI5: 2 | BJ5: 0 | BK5: 3 | BL5: 2 | BM5: 1 | BN5: 1 | BO5: 1 | BP5: 2 | BQ5: 0 | BR5: 2 | BS5: 2 | BT5: 2 | BU5: 2 | BV5: 2 | BW5: 1 | BX5: 2 | BY5: 0 | BZ5: 1 | CA5: 1 | CB5: 3 | CC5: 0 | CD5: 1 | CE5: 2 | CF5: 1 | CG5: 3 | CH5: 2 | CI5: 0 | CJ5: 2 | CK5: 1 | CL5: 0 | CM5: 0 | CN5: 3 | CO5: 1 | CP5: 1 | CQ5: 1 | CR5: 1 | CS5: 2 | CT5: 1 | CU5: 1 | CV5: Pascual | CW5: Neymar | CX5: Argentina | CY5: Brasil
A6: 44884.867 | B6: juanmontoya.derecho@gmail.com | C6: Grupo H | D6: 0 | E6: 2 | F6: 1 | G6: 3 | H6: 0 | I6: 1 | J6: 2 | K6: 1 | L6: 3 | M6: 0 | N6: 2 | O6: 1 | P6: 3 | Q6: 1 | R6: 2 | S6: 1 | T6: 2 | U6: 1 | V6: 1 | W6: 1 | X6: 1 | Y6: 2 | Z6: 0 | AA6: 2 | AB6: 4 | AC6: 0 | AD6: 1 | AE6: 0 | AF6: 2 | AG6: 0 | AH6: 2 | AI6: 0 | AJ6: 1 | AK6: 3 | AL6: 1 | AM6: 2 | AN6: 2 | AO6: 1 | AP6: 2 | AQ6: 0 | AR6: 2 | AS6: 2 | AT6: 1 | AU6: 1 | AV6: 1 | AW6: 2 | AX6: 1 | AY6: 2 | AZ6: 2 | BA6: 1 | BB6: 2 | BC6: 0 | BD6: 2 | BE6: 1 | BF6: 1 | BG6: 1 | BH6: 0 | BI6: 1 | BJ6: 1 | BK6: 3 | BL6: 2 | BM6: 0 | BN6: 1 | BO6: 2 | BP6: 2 | BQ6: 1 | BR6: 1 | BS6: 1 | BT6: 1 | BU6: 2 | BV6: 1 | BW6: 1 | BX6: 1 | BY6: 1 | BZ6: 1 | CA6: 1 | CB6: 2 | CC6: 0 | CD6: 2 | CE6: 1 | CF6: 1 | CG6: 1 | CH6: 2 | CI6: 1 | CJ6: 2 | CK6: 1 | CL6: 2 | CM6: 1 | CN6: 1 | CO6: 2 | CP6: 1 | CQ6: 2 | CR6: 1 | CS6: 2 | CT6: 0 | CU6: 1 | CV6: Juan Esteban Montoya Hincapie | CW6: Lautaro Martínez | CX6: Bélgica | CY6: Argentina
A7: 44884.517 | B7: diegojoseduquegomez@gmail.com | C7: Grupo H | D7: 0 | E7: 2 | F7: 0 | G7: 1 | H7: 1 | I7: 2 | J7: 2 | K7: 2 | L7: 2 | M7: 0 | N7: 0 | O7: 1 | P7: 2 | Q7: 0 | R7: 1 | S7: 0 | T7: 2 | U7: 1 | V7: 2 | W7: 0 | X7: 0 | Y7: 3 | Z7: 0 | AA7: 0 | AB7: 3 | AC7: 0 | AD7: 2 | AE7: 2 | AF7: 3 | AG7: 1 | AH7: 2 | AI7: 0 | AJ7: 0 | AK7: 0 | AL7: 1 | AM7: 1 | AN7: 2 | AO7: 1 | AP7: 1 | AQ7: 0 | AR7: 2 | AS7: 0 | AT7: 1 | AU7: 1 | AV7: 1 | AW7: 3 | AX7: 0 | AY7: 0 | AZ7: 2 | BA7: 0 | BB7: 1 | BC7: 0 | BD7: 2 | BE7: 2 | BF7: 2 | BG7: 0 | BH7: 1 | BI7: 2 | BJ7: 1 | BK7: 4 | BL7: 2 | BM7: 1 | BN7: 1 | BO7: 2 | BP7: 1 | BQ7: 1 | BR7: 2 | BS7: 2 | BT7: 1 | BU7: 0 | BV7: 2 | BW7: 1 | BX7: 4 | BY7: 0 | BZ7: 1 | CA7: 2 | CB7: 3 | CC7: 0 | CD7: 2 | CE7: 1 | CF7: 2 | CG7: 4 | CH7: 1 | CI7: 1 | CJ7: 2 | CK7: 1 | CL7: 2 | CM7: 1 | CN7: 2 | CO7: 2 | CP7: 2 | CQ7: 1 | CR7: 1 | CS7: 3 | CT7: 2 | CU7: 2 | CV7: Emerson Alexis Gomez | CW7: Gabriel Badsa | CX7: Alemania | CY7: Brasil
A8: 44884.517 | B8: cristimesa26@gmail.com | C8: Grupo H | D8: 1 | E8: 2 | F8: 0 | G8: 3 | H8: 0 | I8: 2 | J8: 2 | K8: 0 | L8: 5 | M8: 0 | N8: 1 | O8: 3 | P8: 4 | Q8: 0 | R8: 0 | S8: 1 | T8: 2 | U8: 1 | V8: 2 | W8: 1 | X8: 1 | Y8: 1 | Z8: 0 | AA8: 1 | AB8: 4 | AC8: 0 | AD8: 1 | AE8: 1 | AF8: 2 | AG8: 1 | AH8: 2 | AI8: 0 | AJ8: 1 | AK8: 3 | AL8: 0 | AM8: 1 | AN8: 3 | AO8: 0 | AP8: 2 | AQ8: 1 | AR8: 1 | AS8: 1 | AT8: 1 | AU8: 0 | AV8: 1 | AW8: 3 | AX8: 0 | AY8: 1 | AZ8: 2 | BA8: 0 | BB8: 3 | BC8: 1 | BD8: 0 | BE8: 1 | BF8: 2 | BG8: 2 | BH8: 0 | BI8: 1 | BJ8: 0 | BK8: 2 | BL8: 2 | BM8: 1 | BN8: 1 | BO8: 1 | BP8: 3 | BQ8: 2 | BR8: 2 | BS8: 0 | BT8: 0 | BU8: 1 | BV8: 0 | BW8: 1 | BX8: 0 | BY8: 1 | BZ8: 0 | CA8: 2 | CB8: 3 | CC8: 0 | CD8: 1 | CE8: 1 | CF8: 0 | CG8: 4 | CH8: 2 | CI8: 1 | CJ8: 1 | CK8: 0 | CL8: 3 | CM8: 0 | CN8: 1 | CO8: 1 | CP8: 0 | CQ8: 2 | CR8: 1 | CS8: 3 | CT8: 0 | CU8: 1 | CV8: Pregunte por lo que no vea | CW8: Lionel Messi | CX8: Alemania | CY8: Argentina
A9: 44884.517 | B9: vickastro8@gmail.com | C9: Grupo H | D9: 0 | E9: 1 | F9: 1 | G9: 2 | H9: 0 | I9: 2 | J9: 1 | K9: 0 | L9: 3 | M9: 0 | N9: 1 | O9: 1 | P9: 3 | Q9: 0 | R9: 2 | S9: 1 | T9: 2 | U9: 0 | V9: 1 | W9: 0 | X9: 1 | Y9: 2 | Z9: 1 | AA9: 3 | AB9: 4 | AC9: 0 | AD9: 1 | AE9: 0 | AF9: 2 | AG9: 1 | AH9: 2 | AI9: 0 | AJ9: 1 | AK9: 3 | AL9: 0 | AM9: 3 | AN9: 2 | AO9: 0 | AP9: 1 | AQ9: 0 | AR9: 2 | AS9: 1 | AT9: 1 | AU9: 1 | AV9: 0 | AW9: 1 | AX9: 0 | AY9: 0 | AZ9: 2 | BA9: 1 | BB9: 2 | BC9: 1 | BD9: 0 | BE9: 1 | BF9: 1 | BG9: 0 | BH9: 1 | BI9: 2 | BJ9: 0 | BK9: 3 | BL9: 2 | BM9: 0 | BN9: 0 | BO9: 1 | BP9: 1 | BQ9: 0 | BR9: 1 | BS9: 0 | BT9: 2 | BU9: 2 | BV9: 0 | BW9: 1 | BX9: 4 | BY9: 0 | BZ9: 0 | CA9: 2 | CB9: 3 | CC9: 0 | CD9: 2 | CE9: 1 | CF9: 1 | CG9: 3 | CH9: 0 | CI9: 0 | CJ9: 2 | CK9: 0 | CL9: 1 | CM9: 0 | CN9: 2 | CO9: 1 | CP9: 1 | CQ9: 1 | CR9: 0 | CS9: 3 | CT9: 0 | CU9: 1 | CV9: Casa VIII | CW9: Lionel Messi | CX9: Alemania | CY9: Brasil
A10: 44884.517 | B10: luisfernnaranjo@gmail.com | C10: Grupo H | D10: 1 | E10: 0 | F10: 1 | G10: 2 | H10: 2 | I10: 1 | J10: 3 | K10: 1 | L10: 2 | M10: 0 | N10: 2 | O10: 1 | P10: 4 | Q10: 0 | R10: 1 | S10: 1 | T10: 3 | U10: 1 | V10: 2 | W10: 0 | X10: 1 | Y10: 2 | Z10: 0 | AA10: 1 | AB10: 3 | AC10: 1 | AD10: 1 | AE10: 2 | AF10: 3 | AG10: 1 | AH10: 4 | AI10: 1 | AJ10: 2 | AK10: 2 | AL10: 0 | AM10: 2 | AN10: 2 | AO10: 0 | AP10: 3 | AQ10: 1 | AR10: 2 | AS10: 1 | AT10: 3 | AU10: 2 | AV10: 1 | AW10: 2 | AX10: 0 | AY10: 3 | AZ10: 4 | BA10: 0 | BB10: 3 | BC10: 1 | BD10: 2 | BE10: 2 | BF10: 2 | BG10: 1 | BH10: 0 | BI10: 2 | BJ10: 0 | BK10: 5 | BL10: 2 | BM10: 0 | BN10: 0 | BO10: 1 | BP10: 2 | BQ10: 1 | BR10: 3 | BS10: 0 | BT10: 1 | BU10: 0 | BV10: 1 | BW10: 3 | BX10: 4 | BY10: 1 | BZ10: 1 | CA10: 2 | CB10: 2 | CC10: 1 | CD10: 2 | CE10: 0 | CF10: 2 | CG10: 2 | CH10: 0 | CI10: 1 | CJ10: 2 | CK10: 1 | CL10: 4 | CM10: 1 | CN10: 1 | CO10: 1 | CP10: 1 | CQ10: 2 | CR10: 1 | CS10: 3 | CT10: 2 | CU10: 3 | CV10: Luis Fermin Naranjo Artehourtua | CW10: Vinicius Jose | CX10: Alemania | CY10: Brasil
A11: 44884.517 | B11: sandra.barrientos@udea.edu.co | C11: Grupo H | D11: 1 | E11: 1 | F11: 0 | G11: 2 | H11: 0 | I11: 2 | J11: 3 | K11: 1 | L11: 2 | M11: 1 | N11: 2 | O11: 1 | P11: 3 | Q11: 0 | R11: 1 | S11: 1 | T11: 2 | U11: 1 | V11: 2 | W11: 0 | X11: 1 | Y11: 1 | Z11: 0 | AA11: 3 | AB11: 4 | AC11: 0 | AD11: 1 | AE11: 2 | AF11: 3 | AG11: 0 | AH11: 4 | AI11: 0 | AJ11: 1 | AK11: 2 | AL11: 0 | AM11: 2 | AN11: 2 | AO11: 0 | AP11: 1 | AQ11: 0 | AR11: 1 | AS11: 1 | AT11: 1 | AU11: 0 | AV11: 0 | AW11: 1 | AX11: 0 | AY11: 2 | AZ11: 3 | BA11: 0 | BB11: 2 | BC11: 0 | BD11: 0 | BE11: 1 | BF11: 2 | BG11: 0 | BH11: 0 | BI11: 3 | BJ11: 0 | BK11: 1 | BL11: 3 | BM11: 0 | BN11: 0 | BO11: 2 | BP11: 3 | BQ11: 1 | BR11: 3 | BS11: 0 | BT11: 0 | BU11: 1 | BV11: 0 | BW11: 2 | BX11: 2 | BY11: 0 | BZ11: 1 | CA11: 0 | CB11: 3 | CC11: 0 | CD11: 1 | CE11: 2 | CF11: 0 | CG11: 4 | CH11: 1 | CI11: 0 | CJ11: 4 | CK11: 0 | CL11: 3 | CM11: 1 | CN11: 2 | CO11: 1 | CP11: 0 | CQ11: 1 | CR11: 0 | CS11: 2 | CT11: 0 | CU11: 3 | CV11: Luchismo | CW11: Vinicius Jose | CX11: Brasil | CY11: Argentina
A12: 44884.517 | B12: miralorena@gmail.com | C12: Grupo H | D12: 2 | E12: 0 | F12: 2 | G12: 1 | H12: 1 | I12: 1 | J12: 3 | K12: 2 | L12: 1 | M12: 2 | N12: 2 | O12: 1 | P12: 0 | Q12: 1 | R12: 0 | S12: 1 | T12: 2 | U12: 0 | V12: 2 | W12: 1 | X12: 0 | Y12: 2 | Z12: 2 | AA12: 1 | AB12: 3 | AC12: 0 | AD12: 2 | AE12: 1 | AF12: 2 | AG12: 1 | AH12: 1 | AI12: 3 | AJ12: 2 | AK12: 2 | AL12: 1 | AM12: 3 | AN12: 2 | AO12: 1 | AP12: 3 | AQ12: 1 | AR12: 3 | AS12: 3 | AT12: 1 | AU12: 2 | AV12: 0 | AW12: 3 | AX12: 1 | AY12: 4 | AZ12: 2 | BA12: 3 | BB12: 3 | BC12: 0 | BD12: 0 | BE12: 2 | BF12: 1 | BG12: 0 | BH12: 0 | BI12: 0 | BJ12: 1 | BK12: 3 | BL12: 3 | BM12: 0 | BN12: 4 | BO12: 1 | BP12: 2 | BQ12: 1 | BR12: 0 | BS12: 1 | BT12: 1 | BU12: 2 | BV12: 2 | BW12: 2 | BX12: 4 | BY12: 2 | BZ12: 2 | CA12: 0 | CB12: 2 | CC12: 0 | CD12: 0 | CE12: 0 | CF12: 2 | CG12: 2 | CH12: 1 | CI12: 2 | CJ12: 3 | CK12: 1 | CL12: 3 | CM12: 0 | CN12: 1 | CO12: 1 | CP12: 1 | CQ12: 2 | CR12: 2 | CS12: 3 | CT12: 1 | CU12: 2 | CV12: Lore Mira | CW12: Neymar | CX12: Alemania | CY12: Brasil
A13: 44884.517 | B13: boterovillegas2001@gmail.com | C13: Grupo H | D13: 1 | E13: 2 | F13: 2 | G13: 2 | H13: 0 | I13: 2 | J13: 2 | K13: 1 | L13: 2 | M13: 0 | N13: 2 | O13: 2 | P13: 2 | Q13: 0 | R13: 0 | S13: 1 | T13: 2 | U13: 1 | V13: 1 | W13: 0 | X13: 2 | Y13: 2 | Z13: 0 | AA13: 2 | AB13: 2 | AC13: 0 | AD13: 0 | AE13: 2 | AF13: 3 | AG13: 1 | AH13: 2 | AI13: 0 | AJ13: 2 | AK13: 2 | AL13: 1 | AM13: 2 | AN13: 3 | AO13: 1 | AP13: 2 | AQ13: 0 | AR13: 1 | AS13: 1 | AT13: 2 | AU13: 1 | AV13: 1 | AW13: 2 | AX13: 1 | AY13: 2 | AZ13: 3 | BA13: 0 | BB13: 3 | BC13: 0 | BD13: 1 | BE13: 2 | BF13: 2 | BG13: 2 | BH13: 1 | BI13: 2 | BJ13: 0 | BK13: 2 | BL13: 3 | BM13: 1 | BN13: 0 | BO13: 2 | BP13: 2 | BQ13: 0 | BR13: 2 | BS13: 0 | BT13: 1 | BU13: 2 | BV13: 1 | BW13: 0 | BX13: 2 | BY13: 1 | BZ13: 2 | CA13: 2 | CB13: 3 | CC13: 1 | CD13: 2 | CE13: 2 | CF13: 0 | CG13: 2 | CH13: 1 | CI13: 2 | CJ13: 2 | CK13: 2 | CL13: 2 | CM13: 0 | CN13: 1 | CO13: 2 | CP13: 1 | CQ13: 2 | CR13: 0 | CS13: 3 | CT13: 1 | CU13: 1 | CV13: Alejandro Botero | CW13: Neymar | CX13: Inglaterra | CY13: Brasil
A14: 44884.517 | B14: sandra.barrientos@udea.edu.co | C14: Grupo H | D14: 1 | E14: 1 | F14: 0 | G14: 2 | H14: 1 | I14: 1 | J14: 1 | K14: 2 | L14: 2 | M14: 0 | N14: 2 | O14: 1 | P14: 2 | Q14: 0 | R14: 2 | S14: 0 | T14: 2 | U14: 1 | V14: 0 | W14: 0 | X14: 1 | Y14: 3 | Z14: 0 | AA14: 3 | AB14: 3 | AC14: 0 | AD14: 2 | AE14: 1 | AF14: 1 | AG14: 0 | AH14: 0 | AI14: 1 | AJ14: 0 | AK14: 3 | AL14: 0 | AM14: 2 | AN14: 1 | AO14: 0 | AP14: 3 | AQ14: 0 | AR14: 1 | AS14: 2 | AT14: 1 | AU14: 1 | AV14: 0 | AW14: 2 | AX14: 0 | AY14: 2 | AZ14: 2 | BA14: 2 | BB14: 2 | BC14: 1 | BD14: 2 | BE14: 2 | BF14: 0 | BG14: 1 | BH14: 2 | BI14: 3 | BJ14: 0 | BK14: 3 | BL14: 1 | BM14: 0 | BN14: 0 | BO14: 1 | BP14: 1 | BQ14: 0 | BR14: 2 | BS14: 1 | BT14: 1 | BU14: 1 | BV14: 1 | BW14: 1 | BX14: 1 | BY14: 0 | BZ14: 2 | CA14: 1 | CB14: 2 | CC14: 1 | CD14: 0 | CE14: 2 | CF14: 0 | CG14: 3 | CH14: 0 | CI14: 1 | CJ14: 3 | CK14: 1 | CL14: 2 | CM14: 1 | CN14: 2 | CO14: 2 | CP14: 1 | CQ14: 0 | CR14: 1 | CS14: 2 | CT14: 0 | CU14: 2 | CV14: Guanabano Indigente | CW14: Lautaro Martínez | CX14: Brasil | CY14: Argentina
... A31: 44885.517 | B31: leonardo.valencia@gmail.com | C31: Grupo H | D31: 1 | E31: 1 | F31: 0 | G31: 1 | H31: 2 | I31: 0 | J31: 2 | K31: 1 | L31: 1 | M31: 0 | N31: 1 | O31: 0 | P31: 2 | Q31: 1 | R31: 1 | S31: 0 | T31: 2 | U31: 1 | V31: 1 | W31: 1 | X31: 0 | Y31: 2 | Z31: 0 | AA31: 1 | AB31: 2 | AC31: 1 | AD31: 1 | AE31: 1 | AF31: 2 | AG31: 1 | AH31: 0 | AI31: 0 | AJ31: 0 | AK31: 2 | AL31: 1 | AM31: 2 | AN31: 1 | AO31: 0 | AP31: 2 | AQ31: 0 | AR31: 2 | AS31: 1 | AT31: 0 | AU31: 1 | AV31: 0 | AW31: 2 | AX31: 1 | AY31: 1 | AZ31: 2 | BA31: 0 | BB31: 2 | BC31: 1 | BD31: 2 | BE31: 1 | BF31: 2 | BG31: 0 | BH31: 1 | BI31: 2 | BJ31: 0 | BK31: 3 | BL31: 2 | BM31: 1 | BN31: 0 | BO31: 2 | BP31: 2 | BQ31: 0 | BR31: 2 | BS31: 1 | BT31: 2 | BU31: 2 | BV31: 2 | BW31: 1 | BX31: 2 | BY31: 0 | BZ31: 1 | CA31: 1 | CB31: 2 | CC31: 1 | CD31: 2 | CE31: 1 | CF31: 0 | CG31: 2 | CH31: 1 | CI31: 1 | CJ31: 2 | CK31: 1 | CL31: 2 | CM31: 1 | CN31: 2 | CO31: 2 | CP31: 1 | CQ31: 2 | CR31: 0 | CS31: 1 | CT31: 1 | CU31: 1 | CV31: Leonardo Valencia Valencia | CW31: Leonel Messi | CX31: Brasil | CY31: Argentina

Sheet Puntajes Final
A1: Nombre | B1: Argentina Vs Francia | D1: Croacia Vs Marruecos
B2: Ganador | C2: Puntaje | D2: Ganador | E2: Puntaje | F2: Puntaje Parcial
A3: ='Polla Final'!C18 -> Andres y Cia. | B3: =GANADOR_MARCADOR_POLLA('Polla Final'!D18,'Polla Final'!D2,'Polla Final'!E18,'Polla Final'!E2) -> EMPATE | C3: =PUNTAJE_GANADORES('Polla Final'!D18,'Resultados Oficiales Final'!$C$3,'Polla Final'!E18,'Resultados Oficiales Final'!$D$3,B3,'Resultados Oficiales Final'!$F$3) -> 1 | D3: =GANADOR_MARCADOR_POLLA('Polla Final'!F18,'Polla Final'!F2,'Polla Final'!G18,'Polla Final'!G2) -> EMPATE | E3: =PUNTAJE_GANADORES('Polla Final'!F18,'Resultados Oficiales Final'!$C$2,'Polla Final'!G18,'Resultados Oficiales Final'!$D$2,D3,'Resultados Oficiales Final'!$F$2) -> 1 | F3: =SUM(C3,E3) -> 2
A4: Mauricio Perez (Mauro chef)

Sheet Puntajes Semifinal
A1: Nombre | B1: Argentina Vs Croacia | D1: Francia Vs Marruecos
B2: Ganador | C2: Puntaje | D2: Ganador | E2: Puntaje | F2: Puntaje Parcial
A3: ='Pollas Semifinal'!C3 -> Mauricio Perez (Mauro chef) | B3: =GANADOR_MARCADOR_POLLA('Pollas Semifinal'!D3,'Pollas Semifinal'!$D$2,'Pollas Semifinal'!E3,'Pollas Semifinal'!$E$2) -> Argentina | C3: =PUNTAJE_GANADORES('Pollas Semifinal'!D3,'Resultados SemiFinal Oficiales'!$C$2,'Pollas Semifinal'!E3,'Resultados SemiFinal Oficiales'!$D$2,B3,'Resultados SemiFinal Oficiales'!$F$2) -> 2 | D3: =GANADOR_MARCADOR_POLLA('Pollas Semifinal'!F3,'Pollas Semifinal'!$F$2,'Pollas Semifinal'!G3,'Pollas Semifinal'!$G$2) -> Francia | E3: =PUNTAJE_GANADORES('Pollas Semifinal'!F3,'Resultados SemiFinal Oficiales'!$C$3,'Pollas Semifinal'!G3,'Resultados SemiFinal Oficiales'!$D$3,D3,'Resultados SemiFinal Oficiales'!$F$3) -> 5 | F3: =SUM(C3,E3) -> 7
A4: ='Pollas Semifinal'!C4 -> Leonardo Valencia Valencia | B4: =GANADOR_MARCADOR_POLLA('Pollas Semifinal'!D4,'Pollas Semifinal'!$D$2,'Pollas Semifinal'!E4,'Pollas Semifinal'!$E$2) -> EMPATE | C4: =PUNTAJE_GANADORES('Pollas Semifinal'!D4,'Resultados SemiFinal Oficiales'!$C$2,'Pollas Semifinal'!E4,'Resultados SemiFinal Oficiales'!$D$2,B4,'Resultados SemiFinal Oficiales'!$F$2) -> 0 | D4: =GANADOR_MARCADOR_POLLA('Pollas Semifinal'!F4,'Pollas Semifinal'!$F$2,'Pollas Semifinal'!G4,'Pollas Semifinal'!$G$2) -> Francia | E4: =PUNTAJE_GANADORES('Pollas Semifinal'!F4,'Resultados SemiFinal Oficiales'!$C$3,'Pollas Semifinal'!G4,'Resultados SemiFinal Oficiales'!$D$3,D4,'Resultados SemiFinal Oficiales'!$F$3) -> 3 | F4: =SUM(C4,E4) -> 3
A5: ='Pollas Semifinal'!C5 -> Marta Restrepo | B5: =GANADOR_MARCADOR_POLLA('Pollas Semifinal'!D5,'Pollas Semifinal'!$D$2,'Pollas Semifinal'!E5,'Pollas Semifinal'!$E$2) -> Argentina | C5: =PUNTAJE_GANADORES('Pollas Semifinal'!D5,'Resultados SemiFinal Oficiales'!$C$2,'Pollas Semifinal'!E5,'Resultados SemiFinal Oficiales'!$D$2,B5,'Resultados SemiFinal Oficiales'!$F$2) -> 3 | D5: =GANADOR_MARCADOR_POLLA('Pollas Semifinal'!F5,'Pollas Semifinal'!$F$2,'Pollas Semifinal'!G5,'Pollas Semifinal'!$G$2) -> EMPATE | E5: =PUNTAJE_GANADORES('Pollas Semifinal'!F5,'Resultados SemiFinal Oficiales'!$C$3,'Pollas Semifinal'!G5,'Resultados SemiFinal Oficiales'!$D$3,D5,'Resultados SemiFinal Oficiales'!$F$3) -> 0 | F5: =SUM(C5,E5) -> 3
A6: ='Pollas Semifinal'!C6 -> Emerson Alexis Gomez | B6: =GANADOR_MARCADOR_POLLA('Pollas Semifinal'!D6,'Pollas Semifinal'!$D$2,'Pollas Semifinal'!E6,'Pollas Semifinal'!$E$2) -> Croacia | C6: =PUNTAJE_GANADORES('Pollas Semifinal'!D6,'Resultados SemiFinal Oficiales'!$C$2,'Pollas Semifinal'!E6,'Resultados SemiFinal Oficiales'!$D$2,B6,'Resultados SemiFinal Oficiales'!$F$2) -> 0 | D6: =GANADOR_MARCADOR_POLLA('Pollas Semifinal'!F6,'Pollas Semifinal'!$F$2,'Pollas Semifinal'!G6,'Pollas Semifinal'!$G$2) -> Marruecos | E6: =PUNTAJE_GANADORES('Pollas Semifinal'!F6,'Resultados SemiFinal Oficiales'!$C$3,'Pollas Semifinal'!G6,'Resultados SemiFinal Oficiales'!$D$3,D6,'Resultados SemiFinal Oficiales'!$F$3) -> 0 | F6: =SUM(C6,E6) -> 0
A7: ='Pollas Semifinal'!C7 -> La qatarsis mundial | B7: =GANADOR_MARCADOR_POLLA('Pollas Semifinal'!D7,'Pollas Semifinal'!$D$2,'Pollas Semifinal'!E7,'Pollas Semifinal'!$E$2) -> EMPATE | C7: =PUNTAJE_GANADORES('Pollas Semifinal'!D7,'Resultados SemiFinal Oficiales'!$C$2,'Pollas Semifinal'!E7,'Resultados SemiFinal Oficiales'!$D$2,B7,'Resultados SemiFinal Oficiales'!$F$2) -> 1 | D7: =GANADOR_MARCADOR_POLLA('Pollas Semifinal'!F7,'Pollas Semifinal'!$F$2,'Pollas Semifinal'!G7,'Pollas Semifinal'!$G$2) -> Marruecos | E7: =PUNTAJE_GANADORES('Pollas Semifinal'!F7,'Resultados SemiFinal Oficiales'!$C$3,'Pollas Semifinal'!G7,'Resultados SemiFinal Oficiales'!$D$3,D7,'Resultados SemiFinal Oficiales'!$F$3) -> 1 | F7: =SUM(C7,E7) -> 2
A8: ='Pollas Semifinal'!C8 -> Lore Mira | B8: =GANADOR_MARCADOR_POLLA('Pollas Semifinal'!D8,'Pollas Semifinal'!$D$2,'Pollas Semifinal'!E8,'Pollas Semifinal'!$E$2) -> Croacia | C8: =PUNTAJE_GANADORES('Pollas Semifinal'!D8,'Resultados SemiFinal Oficiales'!$C$2,'Pollas Semifinal'!E8,'Resultados SemiFinal Oficiales'!$D$2,B8,'Resultados SemiFinal Oficiales'!$F$2) -> 0 | D8: =GANADOR_MARCADOR_POLLA('Pollas Semifinal'!F8,'Pollas Semifinal'!$F$2,'Pollas Semifinal'!G8,'Pollas Semifinal'!$G$2) -> Marruecos | E8: =PUNTAJE_GANADORES('Pollas Semifinal'!F8,'Resultados SemiFinal Oficiales'!$C$3,'Pollas Semifinal'!G8,'Resultados SemiFinal Oficiales'!$D$3,D8,'Resultados SemiFinal Oficiales'!$F$3) -> 0 | F8: =SUM(C8,E8) -> 0
A9: ='Pollas Semifinal'!C9 -> TV y Novelas | B9: =GANADOR_MARCADOR_POLLA('Pollas Semifinal'!D9,'Pollas Semifinal'!$D$2,'Pollas Semifinal'!E9,'Pollas Semifinal'!$E$2) -> EMPATE | C9: =PUNTAJE_GANADORES('Pollas Semifinal'!D9,'Resultados SemiFinal Oficiales'!$C$2,'Pollas Semifinal'!E9,'Resultados SemiFinal Oficiales'!$D$2,B9,'Resultados SemiFinal Oficiales'!$F$2) -> 0 | D9: =GANADOR_MARCADOR_POLLA('Pollas Semifinal'!F9,'Pollas Semifinal'!$F$2,'Pollas Semifinal'!G9,'Pollas Semifinal'!$G$2) -> Francia | E9: =PUNTAJE_GANADORES('Pollas Semifinal'!F9,'Resultados SemiFinal Oficiales'!$C$3,'Pollas Semifinal'!G9,'Resultados SemiFinal Oficiales'!$D$3,D9,'Resultados SemiFinal Oficiales'!$F$3) -> 5 | F9: =SUM(C9,E9) -> 5
A10: ='Pollas Semifinal'!C10 -> Luis Fermin Naranjo Artehourtua | B10: =GANADOR_MARCADOR_POLLA('Pollas Semifinal'!D10,'Pollas Semifinal'!$D$2,'Pollas Semifinal'!E10,'Pollas Semifinal'!$E$2) -> Argentina | C10: =PUNTAJE_GANADORES('Pollas Semifinal'!D10,'Resultados SemiFinal Oficiales'!$C$2,'Pollas Semifinal'!E10,'Resultados SemiFinal Oficiales'!$D$2,B10,'Resultados SemiFinal Oficiales'!$F$2) -> 3 | D10: =GANADOR_MARCADOR_POLLA('Pollas Semifinal'!F10,'Pollas Semifinal'!$F$2,'Pollas Semifinal'!G10,'Pollas Semifinal'!$G$2) -> Francia | E10: =PUNTAJE_GANADORES('Pollas Semifinal'!F10,'Resultados SemiFinal Oficiales'!$C$3,'Pollas Semifinal'!G10,'Resultados SemiFinal Oficiales'!$D$3,D10,'Resultados SemiFinal Oficiales'!$F$3) -> 3 | F10: =SUM(C10,E10) -> 6
A11: ='Pollas Semifinal'!C11 -> Las Tejedoras | B11: =GANADOR_MARCADOR_POLLA('Pollas Semifinal'!D11,'Pollas Semifinal'!$D$2,'Pollas Semifinal'!E11,'Pollas Semifinal'!$E$2) -> Argentina | C11: =PUNTAJE_GANADORES('Pollas Semifinal'!D11,'Resultados SemiFinal Oficiales'!$C$2,'Pollas Semifinal'!E11,'Resultados SemiFinal Oficiales'!$D$2,B11,'Resultados SemiFinal Oficiales'!$F$2) -> 3 | D11: =GANADOR_MARCADOR_POLLA('Pollas Semifinal'!F11,'Pollas Semifinal'!$F$2,'Pollas Semifinal'!G11,'Pollas Semifinal'!$G$2) -> Francia | E11: =PUNTAJE_GANADORES('Pollas Semifinal'!F11,'Resultados SemiFinal Oficiales'!$C$3,'Pollas Semifinal'!G11,'Resultados SemiFinal Oficiales'!$D$3,D11,'Resultados SemiFinal Oficiales'!$F$3) -> 3 | F11: =SUM(C11,E11) -> 6
A12: ='Pollas Semifinal'!C12 -> Lolita | B12: =GANADOR_MARCADOR_POLLA('Pollas Semifinal'!D12,'Pollas Semifinal'!$D$2,'Pollas Semifinal'!E12,'Pollas Semifinal'!$E$2) -> Argentina | C12: =PUNTAJE_GANADORES('Pollas Semifinal'!D12,'Resultados SemiFinal Oficiales'!$C$2,'Pollas Semifinal'!E12,'Resultados SemiFinal Oficiales'!$D$2,B12,'Resultados SemiFinal Oficiales'!$F$2) -> 2 | D12: =GANADOR_MARCADOR_POLLA('Pollas Semifinal'!F12,'Pollas Semifinal'!$F$2,'Pollas Semifinal'!G12,'Pollas Semifinal'!$G$2) -> Francia | E12: =PUNTAJE_GANADORES('Pollas Semifinal'!F12,'Resultados SemiFinal Oficiales'!$C$3,'Pollas Semifinal'!G12,'Resultados SemiFinal Oficiales'!$D$3,D12,'Resultados SemiFinal Oficiales'!$F$3) -> 3 | F12: =SUM(C12,E12) -> 5
A13: ='Pollas Semifinal'!C13 -> Los Betancruz | B13: =GANADOR_MARCADOR_POLLA('Pollas Semifinal'!D13,'Pollas Semifinal'!$D$2,'Pollas Semifinal'!E13,'Pollas Semifinal'!$E$2) -> EMPATE | C13: =PUNTAJE_GANADORES('Pollas Semifinal'!D13,'Resultados SemiFinal Oficiales'!$C$2,'Pollas Semifinal'!E13,'Resultados SemiFinal Oficiales'!$D$2,B13,'Resultados SemiFinal Oficiales'!$F$2) -> 0 | D13: =GANADOR_MARCADOR_POLLA('Pollas Semifinal'!F13,'Pollas Semifinal'!$F$2,'Pollas Semifinal'!G13,'Pollas Semifinal'!$G$2) -> Francia | E13: =PUNTAJE_GANADORES('Pollas Semifinal'!F13,'Resultados SemiFinal Oficiales'!$C$3,'Pollas Semifinal'!G13,'Resultados SemiFinal Oficiales'!$D$3,D13,'Resultados SemiFinal Oficiales'!$F$3) -> 3 | F13: =SUM(C13,E13) -> 3
A14: ='Pollas Semifinal'!C14 -> Qatarsis 1.0 | B14: =GANADOR_MARCADOR_POLLA('Pollas Semifinal'!D14,'Pollas Semifinal'!$D$2,'Pollas Semifinal'!E14,'Pollas Semifinal'!$E$2) -> Croacia | C14: =PUNTAJE_GANADORES('Pollas Semifinal'!D14,'Resultados SemiFinal Oficiales'!$C$2,'Pollas Semifinal'!E14,'Resultados SemiFinal Oficiales'!$D$2,B14,'Resultados SemiFinal Oficiales'!$F$2) -> 0 | D14: =GANADOR_MARCADOR_POLLA('Pollas Semifinal'!F14,'Pollas Semifinal'!$F$2,'Pollas Semifinal'!G14,'Pollas Semifinal'!$G$2) -> EMPATE | E14: =PUNTAJE_GANADORES('Pollas Semifinal'!F14,'Resultados SemiFinal Oficiales'!$C$3,'Pollas Semifinal'!G14,'Resultados SemiFinal Oficiales'!$D$3,D14,'Resultados SemiFinal Oficiales'!$F$3) -> 1 | F14: =SUM(C14,E14) -> 1
... A24: ='Pollas Semifinal'!C24 -> Juan Esteban Montoya Hincapie | B24: =GANADOR_MARCADOR_POLLA('Pollas Semifinal'!D24,'Pollas Semifinal'!$D$2,'Pollas Semifinal'!E24,'Pollas Semifinal'!$E$2) -> Argentina | C24: =PUNTAJE_GANADORES('Pollas Semifinal'!D24,'Resultados SemiFinal Oficiales'!$C$2,'Pollas Semifinal'!E24,'Resultados SemiFinal Oficiales'!$D$2,B24,'Resultados SemiFinal Oficiales'!$F$2) -> 3 | D24: =GANADOR_MARCADOR_POLLA('Pollas Semifinal'!F24,'Pollas Semifinal'!$F$2,'Pollas Semifinal'!G24,'Pollas Semifinal'!$G$2) -> Marruecos | E24: =PUNTAJE_GANADORES('Pollas Semifinal'!F24,'Resultados SemiFinal Oficiales'!$C$3,'Pollas Semifinal'!G24,'Resultados SemiFinal Oficiales'!$D$3,D24,'Resultados SemiFinal Oficiales'!$F$3) -> 0 | F24: =SUM(C24,E24) -> 3
A25: ='Pollas Semifinal'!C33 -> Safiro y Acero | B25: =GANADOR_MARCADOR_POLLA('Pollas Semifinal'!D25,'Pollas Semifinal'!$D$2,'Pollas Semifinal'!E25,'Pollas Semifinal'!$E$2) -> Argentina | C25: =PUNTAJE_GANADORES('Pollas Semifinal'!D33,'Resultados SemiFinal Oficiales'!$C$2,'Pollas Semifinal'!E33,'Resultados SemiFinal Oficiales'!$D$2,B25,'Resultados SemiFinal Oficiales'!$F$2) -> 2 | D25: =GANADOR_MARCADOR_POLLA('Pollas Semifinal'!F33,'Pollas Semifinal'!$F$2,'Pollas Semifinal'!G33,'Pollas Semifinal'!$G$2) -> Francia | E25: =PUNTAJE_GANADORES('Pollas Semifinal'!F33,'Resultados SemiFinal Oficiales'!$C$3,'Pollas Semifinal'!G33,'Resultados SemiFinal Oficiales'!$D$3,D25,'Resultados SemiFinal Oficiales'!$F$3) -> 3 | F25: =SUM(C25,E25) -> 5
A26: ='Pollas Semifinal'!C26 -> John Jaramillo-Diogenes Restrepo | B26: =GANADOR_MARCADOR_POLLA('Pollas Semifinal'!D26,'Pollas Semifinal'!$D$2,'Pollas Semifinal'!E26,'Pollas Semifinal'!$E$2) -> Argentina | C26: =PUNTAJE_GANADORES('Pollas Semifinal'!D26,'Resultados SemiFinal Oficiales'!$C$2,'Pollas Semifinal'!E26,'Resultados SemiFinal Oficiales'!$D$2,B26,'Resultados SemiFinal Oficiales'!$F$2) -> 3 | D26: =GANADOR_MARCADOR_POLLA('Pollas Semifinal'!F26,'Pollas Semifinal'!$F$2,'Pollas Semifinal'!G26,'Pollas Semifinal'!$G$2) -> Marruecos | E26: =PUNTAJE_GANADORES('Pollas Semifinal'!F26,'Resultados SemiFinal Oficiales'!$C$3,'Pollas Semifinal'!G26,'Resultados SemiFinal Oficiales'!$D$3,D26,'Resultados SemiFinal Oficiales'!$F$3) -> 0 | F26: =SUM(C26,E26) -> 3
A27: ='Pollas Semifinal'!C27 -> Luchismo | B27: =GANADOR_MARCADOR_POLLA('Pollas Semifinal'!D27,'Pollas Semifinal'!$D$2,'Pollas Semifinal'!E27,'Pollas Semifinal'!$E$2) -> EMPATE | C27: =PUNTAJE_GANADORES('Pollas Semifinal'!D27,'Resultados SemiFinal Oficiales'!$C$2,'Pollas Semifinal'!E27,'Resultados SemiFinal Oficiales'!$D$2,B27,'Resultados SemiFinal Oficiales'!$F$2) -> 0 | D27: =GANADOR_MARCADOR_POLLA('Pollas Semifinal'!F27,'Pollas Semifinal'!$F$2,'Pollas Semifinal'!G27,'Pollas Semifinal'!$G$2) -> Marruecos | E27: =PUNTAJE_GANADORES('Pollas Semifinal'!F27,'Resultados SemiFinal Oficiales'!$C$3,'Pollas Semifinal'!G27,'Resultados SemiFinal Oficiales'!$D$3,D27,'Resultados SemiFinal Oficiales'!$F$3) -> 0 | F27: =SUM(C27,E27) -> 0
A28: ='Pollas Semifinal'!C28 -> Cristina Valentina Echeverri- Las fieras | B28: =GANADOR_MARCADOR_POLLA('Pollas Semifinal'!D28,'Pollas Semifinal'!$D$2,'Pollas Semifinal'!E28,'Pollas Semifinal'!$E$2) -> Croacia | C28: =PUNTAJE_GANADORES('Pollas Semifinal'!D28,'Resultados SemiFinal Oficiales'!$C$2,'Pollas Semifinal'!E28,'Resultados SemiFinal Oficiales'!$D$2,B28,'Resultados SemiFinal Oficiales'!$F$2) -> 0 | D28: =GANADOR_MARCADOR_POLLA('Pollas Semifinal'!F28,'Pollas Semifinal'!$F$2,'Pollas Semifinal'!G28,'Pollas Semifinal'!$G$2) -> Francia | E28: =PUNTAJE_GANADORES('Pollas Semifinal'!F28,'Resultados SemiFinal Oficiales'!$C$3,'Pollas Semifinal'!G28,'Resultados SemiFinal Oficiales'!$D$3,D28,'Resultados SemiFinal Oficiales'!$F$3) -> 3 | F28: =SUM(C28,E28) -> 3
A29: ='Pollas Semifinal'!C29 -> La Perripolla | B29: =GANADOR_MARCADOR_POLLA('Pollas Semifinal'!D29,'Pollas Semifinal'!$D$2,'Pollas Semifinal'!E29,'Pollas Semifinal'!$E$2) -> EMPATE | C29: =PUNTAJE_GANADORES('Pollas Semifinal'!D29,'Resultados SemiFinal Oficiales'!$C$2,'Pollas Semifinal'!E29,'Resultados SemiFinal Oficiales'!$D$2,B29,'Resultados SemiFinal Oficiales'!$F$2) -> 0 | D29: =GANADOR_MARCADOR_POLLA('Pollas Semifinal'!F29,'Pollas Semifinal'!$F$2,'Pollas Semifinal'!G29,'Pollas Semifinal'!$G$2) -> Francia | E29: =PUNTAJE_GANADORES('Pollas Semifinal'!F29,'Resultados SemiFinal Oficiales'!$C$3,'Pollas Semifinal'!G29,'Resultados SemiFinal Oficiales'!$D$3,D29,'Resultados SemiFinal Oficiales'!$F$3) -> 3 | F29: =SUM(C29,E29) -> 3
A30: ='Pollas Semifinal'!C30 -> Ana Maria Corpas | B30: =GANADOR_MARCADOR_POLLA('Pollas Semifinal'!D30,'Pollas Semifinal'!$D$2,'Pollas Semifinal'!E30,'Pollas Semifinal'!$E$2) -> Croacia | C30: =PUNTAJE_GANADORES('Pollas Semifinal'!D30,'Resultados SemiFinal Oficiales'!$C$2,'Pollas Semifinal'!E30,'Resultados SemiFinal Oficiales'!$D$2,B30,'Resultados SemiFinal Oficiales'!$F$2) -> 0 | D30: =GANADOR_MARCADOR_POLLA('Pollas Semifinal'!F30,'Pollas Semifinal'!$F$2,'Pollas Semifinal'!G30,'Pollas Semifinal'!$G$2) -> Francia | E30: =PUNTAJE_GANADORES('Pollas Semifinal'!F30,'Resultados SemiFinal Oficiales'!$C$3,'Pollas Semifinal'!G30,'Resultados SemiFinal Oficiales'!$D$3,D30,'Resultados SemiFinal Oficiales'!$F$3) -> 3 | F30: =SUM(C30,E30) -> 3
A31: ='Pollas Semifinal'!C39 -> Guanabano Indigente | B31: =GANADOR_MARCADOR_POLLA('Pollas Semifinal'!D31,'Pollas Semifinal'!$D$2,'Pollas Semifinal'!E31,'Pollas Semifinal'!$E$2) -> Argentina | C31: =PUNTAJE_GANADORES('Pollas Semifinal'!D31,'Resultados SemiFinal Oficiales'!$C$2,'Pollas Semifinal'!E31,'Resultados SemiFinal Oficiales'!$D$2,B31,'Resultados SemiFinal Oficiales'!$F$2) -> 2 | D31: =GANADOR_MARCADOR_POLLA('Pollas Semifinal'!F31,'Pollas Semifinal'!$F$2,'Pollas Semifinal'!G31,'Pollas Semifinal'!$G$2) -> Francia | E31: =PUNTAJE_GANADORES('Pollas Semifinal'!F31,'Resultados SemiFinal Oficiales'!$C$3,'Pollas Semifinal'!G31,'Resultados SemiFinal Oficiales'!$D$3,D31,'Resultados SemiFinal Oficiales'!$F$3) -> 3 | F31: =SUM(C31,E31) -> 5
A32: ='Pollas Semifinal'!C32

Sheet Resultados Oficiales Final
A1: Fecha | B1: Equipo | C1: Goles | D1: Goles | E1: Equipo | F1: Ganador
A2: 44912 | B2: Croacia | C2: 2 | D2: 1 | E2: Marruecos | F2: =GANADOR_REAL(B2,C2,E2,D2) -> Croacia
A3: 44913 | B3: Argentina | C3: 2 | D3: 2 | E3: Francia | F3: =GANADOR_REAL(B3,C3,E3,D3) -> EMPATE

Sheet Resultados SemiFinal Oficiales
A1: Fecha | B1: Equipo | C1: Goles | D1: Goles | E1: Equipo | F1: Ganador
A2: 44908 | B2: Argentina | C2: 3 | D2: 0 | E2: Croacia | F2: =GANADOR_REAL(B2,C2,E2,D2) -> Argentina
A3: 44909 | B3: Francia | C3: 2 | D3: 0 | E3: Marruecos | F3: =GANADOR_REAL(B3,C3,E3,D3) -> Francia

Sheet Resultados Oficiales Cuartos de
A1: Fecha | B1: Equipo | C1: Goles | D1: Goles | E1: Equipo | F1: Ganador
A2: 44904 | B2: Croacia | C2: 0 | D2: 0 | E2: Brasil | F2: =GANADOR_REAL(B2,C2,E2,D2) -> EMPATE
A3: 44904 | B3: Argentina | C3: 2 | D3: 2 | E3: Paises Bajos | F3: =GANADOR_REAL(B3,C3,E3,D3) -> EMPATE
A4: 44905 | B4: Marruecos | C4: 1 | D4: 0 | E4: Portugal | F4: =GANADOR_REAL(B4,C4,E4,D4) -> Marruecos
A5: 44905 | B5: Inglaterra | C5: 1 | D5: 2 | E5: Francia | F5: =GANADOR_REAL(B5,C5,E5,D5) -> Francia

Sheet Resultados Oficiales Octavos de
A1: Fecha | B1: Equipo | C1: Goles | D1: Goles | E1: Equipo | F1: Ganador
A2: 44898 | B2: Paises Bajos | C2: 3 | D2: 1 | E2: Estados Unidos | F2: =GANADOR_REAL(B2,C2,E2,D2) -> Paises Bajos
A3: 44898 | B3: Argentina | C3: 2 | D3: 1 | E3: Australia | F3: =GANADOR_REAL(B3,C3,E3,D3) -> Argentina
A4: 44899 | B4: Francia | C4: 3 | D4: 1 | E4: Polonia | F4: =GANADOR_REAL(B4,C4,E4,D4) -> Francia
A5: 44899 | B5: Inglaterra | C5: 3 | D5: 0 | E5: Senegal | F5: =GANADOR_REAL(B5,C5,E5,D5) -> Inglaterra
A6: 44900 | B6: Japón | C6: 1 | D6: 1 | E6: Croacia | F6: =GANADOR_REAL(B6,C6,E6,D6) -> EMPATE
A7: 44900 | B7: Brasil | C7: 4 | D7: 1 | E7: Corea del Sur | F7: =GANADOR_REAL(B7,C7,E7,D7) -> Brasil
A8: 44901 | B8: Marruecos | C8: 0 | D8: 0 | E8: España | F8: =GANADOR_REAL(B8,C8,E8,D8) -> EMPATE
A9: 44901 | B9: Portugal | C9: 6 | D9: 1 | E9: Suiza | F9: =GANADOR_REAL(B9,C9,E9,D9) -> Portugal

Sheet Resultados Oficiales Fase de Gr
B2: Fecha | D2: Goles | E2: Goles | G2: GANADOR
A3: A | B3: 44885 | C3: Qatar | D3: 0 | E3: 2 | F3: Ecuador | G3: =GANADOR_REAL(C3,D3,F3,E3) -> Ecuador | I3: Grupo A
B4: 44886 | C4: Senegal | D4: 0 | E4: 2 | F4: Paises Bajos | G4: =GANADOR_REAL(C4,D4,F4,E4) -> Paises Bajos | I4: Pos | J4: Selección | K4: Pts | L4: J | M4: G | N4: E | O4: P | P4: GF | Q4: GC | R4: DG
B5: 44890 | C5: Qatar | D5: 1 | E5: 3 | F5: Senegal | G5: =GANADOR_REAL(C5,D5,F5,E5) -> Senegal | I5: 1 | J5: Ecuador | K5: =PUNTAJE(E3,D3,E6,D6,D8,E8) -> 4 | L5: =JUGADOS(E3,E6,D8) -> 3 | M5: =PARTIDOS_GANADOS(E3,D3,E6,D6,D8,E8) -> 1 | N5: =PARTIDOS_EMPATADOS(E3,D3,E6,D6,D8,E8) -> 1 | O5: =PARTIDOS_PERDIDOS(E3,D3,E6,D6,D8,E8) -> 1 | P5: =GOLES_FAVOR(E3,E6,D8) -> 4 | Q5: =GOLES_CONTRA(D3,D6,E8) -> 3 | R5: =P5-Q5 -> 1
